<?xml version="1.0" encoding="utf-8"?>
<!-- =================================================================================== -->
<!--   Copyright 2020 ANYbotics, https://www.anybotics.com                               -->
<!-- =================================================================================== -->
<!-- This file contains the description of the ANYmal C robot. -->
<robot name="anymal">
    <!-- Base link -->
    <link name="base">
        <visual>
            <origin rpy="0 0 0" xyz="0 0 0"/>
            <geometry>
                <mesh filename="../anymal_c_simple_description/meshes/base.dae" scale="1.0 1.0 1.0"/>
            </geometry>
        </visual>
        <collision>
            <origin rpy="0 0 0" xyz="0 0 0"/>
            <geometry>
                <box size="0.58 0.14 0.18"/>
            </geometry>
        </collision>
        <collision>
            <origin rpy="0 1.57079632679 0" xyz="0.2175 0.07 0"/>
            <geometry>
                <cylinder length="0.145" radius="0.09"/>
            </geometry>
        </collision>
        <collision>
            <origin rpy="0 1.57079632679 0" xyz="-0.2175 0.07 0"/>
            <geometry>
                <cylinder length="0.145" radius="0.09"/>
            </geometry>
        </collision>
        <collision>
            <origin rpy="0 1.57079632679 0" xyz="0.2175 -0.07 0"/>
            <geometry>
                <cylinder length="0.145" radius="0.09"/>
            </geometry>
        </collision>
        <collision>
            <origin rpy="0 1.57079632679 0" xyz="-0.2175 -0.07 0"/>
            <geometry>
                <cylinder length="0.145" radius="0.09"/>
            </geometry>
        </collision>
        <!-- Shell self filtering -->
        <self_filter>
            <origin rpy="0 0 0" xyz="0 0 0"/>
            <geometry>
                <box size="1.05 0.5 0.5"/>
            </geometry>
        </self_filter>
    </link>
    <!-- Fixed joint to add dummy inertia link -->
    <joint name="base_to_base_inertia" type="fixed">
        <parent link="base"/>
        <child link="base_inertia"/>
        <origin rpy="0 0 0" xyz="0 0 0"/>
    </joint>
    <!-- Dummy inertia link, because KDL cannot have inertia on the base link -->
    <link name="base_inertia">
        <inertial>
            <origin rpy="0 0 0" xyz="-0.018 -0.002 0.024"/>
            <mass value="6.222"/>
            <inertia ixx="0.017938806" ixy="0.00387963" ixz="0.001500772" iyy="0.370887745" iyz="6.8963e-05" izz="0.372497653"/>
        </inertial>
    </link>
    <!-- Fixed joint base topshell -->
    <joint name="base_top_shell" type="fixed">
        <parent link="base"/>
        <child link="top_shell"/>
        <origin rpy="0 0 0" xyz="0 0 0"/>
    </joint>
    <!-- Top shell link -->
    <link name="top_shell">
        <visual>
            <origin rpy="0 0 0" xyz="0 0 0"/>
            <geometry>
                <mesh filename="../anymal_c_simple_description/meshes/top_shell.dae" scale="1.0 1.0 1.0"/>
            </geometry>
        </visual>
        <inertial>
            <origin rpy="0 0 0" xyz="-0.00777 -0.00013 0.06523"/>
            <mass value="0.534"/>
            <inertia ixx="0.00664789486" ixy="1.247923e-05" ixz="0.00053990097" iyy="0.02587392411" iyz="3.7614e-07" izz="0.03152303792"/>
        </inertial>
    </link>
    <!-- Fixed joint base topshell -->
    <joint name="base_bottom_shell" type="fixed">
        <parent link="base"/>
        <child link="bottom_shell"/>
        <origin rpy="0 0 0" xyz="0 0 0"/>
    </joint>
    <!-- Bottom shell link -->
    <link name="bottom_shell">
        <visual>
            <origin rpy="0 0 0" xyz="0 0 0"/>
            <geometry>
                <mesh filename="../anymal_c_simple_description/meshes/bottom_shell.dae" scale="1.0 1.0 1.0"/>
            </geometry>
        </visual>
        <inertial>
            <origin rpy="0 0 0" xyz="-0.00333 1e-05 -0.07705"/>
            <mass value="1.15"/>
            <inertia ixx="0.00927353677" ixy="5.41222e-06" ixz="9.039821e-05" iyy="0.06134388239" iyz="2.3042e-07" izz="0.06853531465"/>
        </inertial>
    </link>
    <!-- Fixed joint base remote -->
    <joint name="base_remote" type="fixed">
        <parent link="base"/>
        <child link="remote"/>
        <origin rpy="0 0 0" xyz="0 0 0"/>
    </joint>
    <!-- Remote link -->
    <link name="remote">
        <visual>
            <origin rpy="0 0 0" xyz="0 0 0"/>
            <geometry>
                <mesh filename="../anymal_c_simple_description/meshes/remote.dae" scale="1.0 1.0 1.0"/>
            </geometry>
        </visual>
        <inertial>
            <origin rpy="0 0 0" xyz="-0.171 0.002 0.096"/>
            <mass value="0.3262"/>
            <inertia ixx="0.000528486" ixy="4.547e-05" ixz="1.10327e-05" iyy="0.001165035" iyz="7.4e-07" izz="0.00124026"/>
        </inertial>
    </link>
    <!-- Fixed joint base handle -->
    <!-- <joint name="base_handle" type="fixed">
        <parent link="base"/>
        <child link="handle"/>
        <origin rpy="0 0 0" xyz="0 0 0"/>
    </joint> -->
    <!-- Handle link -->
    <!-- <link name="handle">
        <visual>
            <origin rpy="0 0 0" xyz="0 0 0"/>
            <geometry>
                <mesh filename="../anymal_c_simple_description/meshes/handle.dae" scale="1.0 1.0 1.0"/>
            </geometry>
        </visual>
        <inertial>
            <origin rpy="0 0 0" xyz="0.37801 0.0 0.1372"/>
            <mass value="0.314"/>
            <inertia ixx="0.001525739" ixy="0.0" ixz="6.272e-05" iyy="0.00071584" iyz="1e-09" izz="0.001164779"/>
        </inertial>
    </link> -->
    <!-- Fixed joint base face -->
    <joint name="base_face_front" type="fixed">
        <parent link="base"/>
        <child link="face_front"/>
        <origin rpy="0 0 -0.0" xyz="0.4145 0 0"/>
    </joint>
    <!-- Shell link -->
    <link name="face_front">
        <visual>
            <origin rpy="0 0 0" xyz="0 0 0"/>
            <geometry>
                <mesh filename="../anymal_c_simple_description/meshes/face.dae" scale="1.0 1.0 1.0"/>
            </geometry>
        </visual>
        <collision>
            <origin rpy="0 0 0" xyz="0.055 0 0"/>
            <geometry>
                <box size="0.11 0.14 0.18"/>
            </geometry>
        </collision>
        <collision>
            <origin rpy="0 1.57079632679 0" xyz="0.055 0.07 0"/>
            <geometry>
                <cylinder length="0.11" radius="0.09"/>
            </geometry>
        </collision>
        <collision>
            <origin rpy="0 1.57079632679 0" xyz="0.055 -0.07 0"/>
            <geometry>
                <cylinder length="0.11" radius="0.09"/>
            </geometry>
        </collision>
        <inertial>
            <origin rpy="0 0 0" xyz="0.042 -0.001 0.004"/>
            <mass value="0.73"/>
            <inertia ixx="0.005238611" ixy="1.7609e-05" ixz="7.2167e-05" iyy="0.002643098" iyz="1.9548e-05" izz="0.004325938"/>
        </inertial>
    </link>
    <!-- Camera joint -->
    <!-- Is located between the two back screw holes at ground level. -->
    <joint name="face_front_to_depth_camera_front_camera" type="fixed">
        <parent link="face_front"/>
        <child link="depth_camera_front_camera"/>
        <origin rpy="0.0 0.523598775598 0" xyz="0.04715 0.0 -0.0292"/>
    </joint>
    <!-- Camera link -->
    <link name="depth_camera_front_camera">
        <visual>
            <origin rpy="0 0 0" xyz="0.0 0.0 0.0"/>
            <geometry>
                <mesh filename="../anymal_c_simple_description/meshes/depth_camera.dae" scale="1.0 1.0 1.0"/>
            </geometry>
        </visual>
        <inertial>
            <origin rpy="0 0 0" xyz="-0.021 -0.002 0.025"/>
            <mass value="0.16043"/>
            <inertia ixx="0.000637051" ixy="0.000484569" ixz="0.000424211" iyy="0.000929402" iyz="5.138e-06" izz="0.000484569"/>
        </inertial>
    </link>
    <!-- Camera parent joint -->
    <!-- Frame lies on the left ir camera according to any_realsense2_camera urdf. -->
    <joint name="depth_camera_front_camera_to_camera_parent" type="fixed">
        <parent link="depth_camera_front_camera"/>
        <child link="depth_camera_front_camera_parent"/>
        <origin rpy="0.0 0.0 0.0" xyz="0.0255 0.0175 0.0"/>
    </joint>
    <!-- Camera parent link -->
    <link name="depth_camera_front_camera_parent"/>
    <!-- Depth optical frame joint -->
    <joint name="depth_camera_front_camera_parent_to_depth_optical_frame" type="fixed">
        <parent link="depth_camera_front_camera_parent"/>
        <child link="depth_camera_front_depth_optical_frame"/>
        <origin rpy="-1.57079632679 0.0 -1.57079632679" xyz="0.0 0.0 0.0"/>
    </joint>
    <!-- Depth optical frame link -->
    <link name="depth_camera_front_depth_optical_frame"/>
    <!-- Camera color frame joint -->
    <joint name="depth_camera_front_camera_parent_to_color_frame" type="fixed">
        <parent link="depth_camera_front_camera_parent"/>
        <child link="depth_camera_front_color_frame"/>
        <origin rpy="0 0 0" xyz="0 0.015 0"/>
    </joint>
    <!-- Camera color frame link -->
    <link name="depth_camera_front_color_frame"/>
    <!-- Camera color optical joint -->
    <joint name="depth_camera_front_color_frame_to_color_optical_frame" type="fixed">
        <parent link="depth_camera_front_color_frame"/>
        <child link="depth_camera_front_color_optical_frame"/>
        <origin rpy="-1.57079632679 0.0 -1.57079632679" xyz="0.0 0.0 0.0"/>
    </joint>
    <!-- Camera color optical link -->
    <link name="depth_camera_front_color_optical_frame"/>
    <!-- Camera joint -->
    <!-- Is located in the center of the mounting points. -->
    <joint name="face_front_to_wide_angle_camera_front_camera" type="fixed">
        <parent link="face_front"/>
        <child link="wide_angle_camera_front_camera"/>
        <origin rpy="0 0 0" xyz="0.09850 0.0 0.01497"/>
    </joint>
    <!-- Camera link -->
    <link name="wide_angle_camera_front_camera">
        <visual>
            <origin rpy="0 0 0" xyz="0.0 0.0 0.0"/>
            <geometry>
                <mesh filename="../anymal_c_simple_description/meshes/wide_angle_camera.dae" scale="1.0 1.0 1.0"/>
            </geometry>
        </visual>
        <inertial>
            <origin rpy="0 0 0" xyz="-0.053 -0.001 0.025"/>
            <mass value="0.287"/>
            <inertia ixx="0.000559232" ixy="1.6875e-05" ixz="0.000423761" iyy="0.000946504" iyz="1.3234e-07" izz="0.000493052"/>
        </inertial>
    </link>
    <!-- Camera parent joint -->
    <joint name="wide_angle_camera_front_camera_to_camera_parent" type="fixed">
        <parent link="wide_angle_camera_front_camera"/>
        <child link="wide_angle_camera_front_camera_parent"/>
        <origin rpy="-1.57079632679 0.0 -1.57079632679" xyz="0.0 0.0 0.0"/>
    </joint>
    <!-- Camera parent link -->
    <link name="wide_angle_camera_front_camera_parent"/>
    <!-- Fixed joint base face -->
    <joint name="base_face_rear" type="fixed">
        <parent link="base"/>
        <child link="face_rear"/>
        <origin rpy="0 0 3.14159265359" xyz="-0.4145 0 0"/>
    </joint>
    <!-- Shell link -->
    <link name="face_rear">
        <visual>
            <origin rpy="0 0 0" xyz="0 0 0"/>
            <geometry>
                <mesh filename="../anymal_c_simple_description/meshes/face.dae" scale="1.0 1.0 1.0"/>
            </geometry>
        </visual>
        <collision>
            <origin rpy="0 0 0" xyz="0.055 0 0"/>
            <geometry>
                <box size="0.11 0.14 0.18"/>
            </geometry>
        </collision>
        <collision>
            <origin rpy="0 1.57079632679 0" xyz="0.055 0.07 0"/>
            <geometry>
                <cylinder length="0.11" radius="0.09"/>
            </geometry>
        </collision>
        <collision>
            <origin rpy="0 1.57079632679 0" xyz="0.055 -0.07 0"/>
            <geometry>
                <cylinder length="0.11" radius="0.09"/>
            </geometry>
        </collision>
        <inertial>
            <origin rpy="0 0 0" xyz="0.042 -0.001 0.004"/>
            <mass value="0.73"/>
            <inertia ixx="0.005238611" ixy="1.7609e-05" ixz="7.2167e-05" iyy="0.002643098" iyz="1.9548e-05" izz="0.004325938"/>
        </inertial>
    </link>
    <!-- Camera joint -->
    <!-- Is located between the two back screw holes at ground level. -->
    <joint name="face_rear_to_depth_camera_rear_camera" type="fixed">
        <parent link="face_rear"/>
        <child link="depth_camera_rear_camera"/>
        <origin rpy="0.0 0.523598775598 0" xyz="0.04715 0.0 -0.0292"/>
    </joint>
    <!-- Camera link -->
    <link name="depth_camera_rear_camera">
        <visual>
            <origin rpy="0 0 0" xyz="0.0 0.0 0.0"/>
            <geometry>
                <mesh filename="../anymal_c_simple_description/meshes/depth_camera.dae" scale="1.0 1.0 1.0"/>
            </geometry>
        </visual>
        <inertial>
            <origin rpy="0 0 0" xyz="-0.021 -0.002 0.025"/>
            <mass value="0.16043"/>
            <inertia ixx="0.000637051" ixy="0.000484569" ixz="0.000424211" iyy="0.000929402" iyz="5.138e-06" izz="0.000484569"/>
        </inertial>
    </link>
    <!-- Camera parent joint -->
    <!-- Frame lies on the left ir camera according to any_realsense2_camera urdf. -->
    <joint name="depth_camera_rear_camera_to_camera_parent" type="fixed">
        <parent link="depth_camera_rear_camera"/>
        <child link="depth_camera_rear_camera_parent"/>
        <origin rpy="0.0 0.0 0.0" xyz="0.0255 0.0175 0.0"/>
    </joint>
    <!-- Camera parent link -->
    <link name="depth_camera_rear_camera_parent"/>
    <!-- Depth optical frame joint -->
    <joint name="depth_camera_rear_camera_parent_to_depth_optical_frame" type="fixed">
        <parent link="depth_camera_rear_camera_parent"/>
        <child link="depth_camera_rear_depth_optical_frame"/>
        <origin rpy="-1.57079632679 0.0 -1.57079632679" xyz="0.0 0.0 0.0"/>
    </joint>
    <!-- Depth optical frame link -->
    <link name="depth_camera_rear_depth_optical_frame"/>
    <!-- Camera color frame joint -->
    <joint name="depth_camera_rear_camera_parent_to_color_frame" type="fixed">
        <parent link="depth_camera_rear_camera_parent"/>
        <child link="depth_camera_rear_color_frame"/>
        <origin rpy="0 0 0" xyz="0 0.015 0"/>
    </joint>
    <!-- Camera color frame link -->
    <link name="depth_camera_rear_color_frame"/>
    <!-- Camera color optical joint -->
    <joint name="depth_camera_rear_color_frame_to_color_optical_frame" type="fixed">
        <parent link="depth_camera_rear_color_frame"/>
        <child link="depth_camera_rear_color_optical_frame"/>
        <origin rpy="-1.57079632679 0.0 -1.57079632679" xyz="0.0 0.0 0.0"/>
    </joint>
    <!-- Camera color optical link -->
    <link name="depth_camera_rear_color_optical_frame"/>
    <!-- Camera joint -->
    <!-- Is located in the center of the mounting points. -->
    <joint name="face_rear_to_wide_angle_camera_rear_camera" type="fixed">
        <parent link="face_rear"/>
        <child link="wide_angle_camera_rear_camera"/>
        <origin rpy="0 0 0" xyz="0.09850 0.0 0.01497"/>
    </joint>
    <!-- Camera link -->
    <link name="wide_angle_camera_rear_camera">
        <visual>
            <origin rpy="0 0 0" xyz="0.0 0.0 0.0"/>
            <geometry>
                <mesh filename="../anymal_c_simple_description/meshes/wide_angle_camera.dae" scale="1.0 1.0 1.0"/>
            </geometry>
        </visual>
        <inertial>
            <origin rpy="0 0 0" xyz="-0.053 -0.001 0.025"/>
            <mass value="0.287"/>
            <inertia ixx="0.000559232" ixy="1.6875e-05" ixz="0.000423761" iyy="0.000946504" iyz="1.3234e-07" izz="0.000493052"/>
        </inertial>
    </link>
    <!-- Camera parent joint -->
    <joint name="wide_angle_camera_rear_camera_to_camera_parent" type="fixed">
        <parent link="wide_angle_camera_rear_camera"/>
        <child link="wide_angle_camera_rear_camera_parent"/>
        <origin rpy="-1.57079632679 0.0 -1.57079632679" xyz="0.0 0.0 0.0"/>
    </joint>
    <!-- Camera parent link -->
    <link name="wide_angle_camera_rear_camera_parent"/>
    <!-- Fixed joint base battery -->
    <joint name="base_battery" type="fixed">
        <parent link="base"/>
        <child link="battery"/>
        <origin rpy="0 0 0" xyz="0 0 0"/>
    </joint>
    <!-- Shell link -->
    <link name="battery">
        <visual>
            <origin rpy="0 0 0" xyz="0 0 0"/>
            <geometry>
                <mesh filename="../anymal_c_simple_description/meshes/battery.dae" scale="1.0 1.0 1.0"/>
            </geometry>
        </visual>
        <inertial>
            <origin rpy="0 0 0" xyz="-0.00067 -0.00023 -0.03362"/>
            <mass value="5.53425"/>
            <inertia ixx="0.00749474794" ixy="0.00016686282" ixz="7.82763e-05" iyy="0.0722338913" iyz="1.42902e-06" izz="0.07482717535"/>
        </inertial>
    </link>
    <!-- Fixed joint to add docking  -->
    <joint name="base_to_docking_hatch_cover" type="fixed">
        <parent link="base"/>
        <child link="docking_hatch_cover"/>
        <origin rpy="0 0 0" xyz="0.343 0.0 -0.07"/>
    </joint>
    <!-- Hatch cover link -->
    <link name="docking_hatch_cover">
        <!--  TODO(fgiraldez): add visual    -->
        <inertial>
            <origin rpy="0 0 0" xyz="-0.003 0.0 0.005"/>
            <mass value="0.065"/>
            <inertia ixx="0.00063283" ixy="0.0" ixz="3.45e-07" iyy="0.00110971" iyz="0.0" izz="0.00171883"/>
        </inertial>
    </link>
    <link name="imu_link">
        <visual>
            <origin rpy="0 0 0" xyz="0 0 0.005"/>
            <geometry>
                <box size="0.024 0.024 0.01"/>
            </geometry>
            <material name="orange"/>
        </visual>
        <collision>
            <origin rpy="0 0 0" xyz="0 0 0.005"/>
            <geometry>
                <box size="0.024 0.024 0.01"/>
            </geometry>
        </collision>
        <inertial>
            <mass value="0.01"/>
            <origin xyz="0 0 0"/>
            <inertia ixx="5.63333333333e-07" ixy="0.0" ixz="0.0" iyy="9.6e-07" iyz="0.0" izz="5.63333333333e-07"/>
        </inertial>
    </link>
    <joint name="imu_joint" type="fixed">
        <parent link="base"/>
        <child link="imu_link"/>
        <origin rpy="0.0 0.0 1.57079632679" xyz="0.2488 0.00835 0.04628"/>
    </joint>
    <!-- Camera joint -->
    <!-- Is located between the two back screw holes at ground level. -->
    <joint name="base_to_depth_camera_left_camera" type="fixed">
        <parent link="base"/>
        <child link="depth_camera_left_camera"/>
        <origin rpy="0.0 0.523598775598 1.57079632679" xyz="0.0 0.07646 0.02905"/>
    </joint>
    <!-- Camera link -->
    <link name="depth_camera_left_camera">
        <visual>
            <origin rpy="0 0 0" xyz="0.0 0.0 0.0"/>
            <geometry>
                <mesh filename="../anymal_c_simple_description/meshes/depth_camera.dae" scale="1.0 1.0 1.0"/>
            </geometry>
        </visual>
        <inertial>
            <origin rpy="0 0 0" xyz="-0.021 -0.002 0.025"/>
            <mass value="0.16043"/>
            <inertia ixx="0.000637051" ixy="0.000484569" ixz="0.000424211" iyy="0.000929402" iyz="5.138e-06" izz="0.000484569"/>
        </inertial>
    </link>
    <!-- Camera parent joint -->
    <!-- Frame lies on the left ir camera according to any_realsense2_camera urdf. -->
    <joint name="depth_camera_left_camera_to_camera_parent" type="fixed">
        <parent link="depth_camera_left_camera"/>
        <child link="depth_camera_left_camera_parent"/>
        <origin rpy="0.0 0.0 0.0" xyz="0.0255 0.0175 0.0"/>
    </joint>
    <!-- Camera parent link -->
    <link name="depth_camera_left_camera_parent"/>
    <!-- Depth optical frame joint -->
    <joint name="depth_camera_left_camera_parent_to_depth_optical_frame" type="fixed">
        <parent link="depth_camera_left_camera_parent"/>
        <child link="depth_camera_left_depth_optical_frame"/>
        <origin rpy="-1.57079632679 0.0 -1.57079632679" xyz="0.0 0.0 0.0"/>
    </joint>
    <!-- Depth optical frame link -->
    <link name="depth_camera_left_depth_optical_frame"/>
    <!-- Camera color frame joint -->
    <joint name="depth_camera_left_camera_parent_to_color_frame" type="fixed">
        <parent link="depth_camera_left_camera_parent"/>
        <child link="depth_camera_left_color_frame"/>
        <origin rpy="0 0 0" xyz="0 0.015 0"/>
    </joint>
    <!-- Camera color frame link -->
    <link name="depth_camera_left_color_frame"/>
    <!-- Camera color optical joint -->
    <joint name="depth_camera_left_color_frame_to_color_optical_frame" type="fixed">
        <parent link="depth_camera_left_color_frame"/>
        <child link="depth_camera_left_color_optical_frame"/>
        <origin rpy="-1.57079632679 0.0 -1.57079632679" xyz="0.0 0.0 0.0"/>
    </joint>
    <!-- Camera color optical link -->
    <link name="depth_camera_left_color_optical_frame"/>
    <!-- Camera joint -->
    <!-- Is located between the two back screw holes at ground level. -->
    <joint name="base_to_depth_camera_right_camera" type="fixed">
        <parent link="base"/>
        <child link="depth_camera_right_camera"/>
        <origin rpy="0.0 0.523598775598 -1.57079632679" xyz="0.0 -0.07646 0.02905"/>
    </joint>
    <!-- Camera link -->
    <link name="depth_camera_right_camera">
        <visual>
            <origin rpy="0 0 0" xyz="0.0 0.0 0.0"/>
            <geometry>
                <mesh filename="../anymal_c_simple_description/meshes/depth_camera.dae" scale="1.0 1.0 1.0"/>
            </geometry>
        </visual>
        <inertial>
            <origin rpy="0 0 0" xyz="-0.021 -0.002 0.025"/>
            <mass value="0.16043"/>
            <inertia ixx="0.000637051" ixy="0.000484569" ixz="0.000424211" iyy="0.000929402" iyz="5.138e-06" izz="0.000484569"/>
        </inertial>
    </link>
    <!-- Camera parent joint -->
    <!-- Frame lies on the left ir camera according to any_realsense2_camera urdf. -->
    <joint name="depth_camera_right_camera_to_camera_parent" type="fixed">
        <parent link="depth_camera_right_camera"/>
        <child link="depth_camera_right_camera_parent"/>
        <origin rpy="0.0 0.0 0.0" xyz="0.0255 0.0175 0.0"/>
    </joint>
    <!-- Camera parent link -->
    <link name="depth_camera_right_camera_parent"/>
    <!-- Depth optical frame joint -->
    <joint name="depth_camera_right_camera_parent_to_depth_optical_frame" type="fixed">
        <parent link="depth_camera_right_camera_parent"/>
        <child link="depth_camera_right_depth_optical_frame"/>
        <origin rpy="-1.57079632679 0.0 -1.57079632679" xyz="0.0 0.0 0.0"/>
    </joint>
    <!-- Depth optical frame link -->
    <link name="depth_camera_right_depth_optical_frame"/>
    <!-- Camera color frame joint -->
    <joint name="depth_camera_right_camera_parent_to_color_frame" type="fixed">
        <parent link="depth_camera_right_camera_parent"/>
        <child link="depth_camera_right_color_frame"/>
        <origin rpy="0 0 0" xyz="0 0.015 0"/>
    </joint>
    <!-- Camera color frame link -->
    <link name="depth_camera_right_color_frame"/>
    <!-- Camera color optical joint -->
    <joint name="depth_camera_right_color_frame_to_color_optical_frame" type="fixed">
        <parent link="depth_camera_right_color_frame"/>
        <child link="depth_camera_right_color_optical_frame"/>
        <origin rpy="-1.57079632679 0.0 -1.57079632679" xyz="0.0 0.0 0.0"/>
    </joint>
    <!-- Camera color optical link -->
    <link name="depth_camera_right_color_optical_frame"/>
    <!-- parent to cage joint, located between mounting plate on trunk and the cage -->
    <joint name="base_to_lidar_cage" type="fixed">
        <parent link="base"/>
        <child link="lidar_cage"/>
        <origin rpy="0 0 0" xyz="-0.364 0.0 0.0735"/>
    </joint>
    <!-- Velodyne cage link -->
    <link name="lidar_cage">
        <visual>
            <origin rpy="0.0 0.0 0.0" xyz="0.0 0.0 0.0"/>
            <geometry>
                <mesh filename="../anymal_c_simple_description/meshes/lidar_cage.dae" scale="1.0 1.0 1.0"/>
            </geometry>
        </visual>
        <collision>
            <origin rpy="0 0 0" xyz="0 0 0.06"/>
            <geometry>
                <cylinder length="0.12" radius="0.07"/>
            </geometry>
        </collision>
        <inertial>
            <origin rpy="0.0 0.0 0.0" xyz="0.002 0.0 0.099"/>
            <mass value="0.545"/>
            <inertia ixx="0.003156254" ixy="0.0" ixz="1.0992e-05" iyy="0.002357216" iyz="0.0" izz="0.001326455"/>
        </inertial>
    </link>
    <!-- parent to sensor joint -->
    <joint name="lidar_cage_to_lidar" type="fixed">
        <parent link="lidar_cage"/>
        <child link="lidar"/>
        <origin rpy="0.0 0.0 -1.57079632679" xyz="0.0 0.0 0.0687"/>
    </joint>
    <!-- Velodyne sensor link -->
    <link name="lidar">
        <inertial>
            <origin rpy="0.0 0.0 0.0" xyz="-0.012 0.001 -0.008"/>
            <mass value="0.695"/>
            <inertia ixx="0.000846765" ixy="6.9565e-05" ixz="0.00027111" iyy="0.001367583" iyz="5.8984e-05" izz="0.001363673"/>
        </inertial>
        <visual>
            <origin xyz="0 0 0"/>
            <geometry>
                <mesh filename="../anymal_c_simple_description/meshes/lidar.dae"/>
            </geometry>
        </visual>
    </link>
    <!-- joint base HAA -->
    <joint name="base_LF_HAA" type="fixed">
        <parent link="base"/>
        <child link="LF_HAA"/>
        <origin rpy="2.61799387799 0 0.0" xyz="0.2999 0.104 0.0"/>
    </joint>
    <!-- Drive link -->
    <link name="LF_HAA">
        <visual>
            <origin rpy="0 0 0" xyz="0 0 0"/>
            <geometry>
                <mesh filename="../anymal_c_simple_description/meshes/drive.dae" scale="1.0 1.0 1.0"/>
            </geometry>
        </visual>
        <inertial>
            <origin rpy="0 0 0" xyz="-0.063 7e-05 0.00046"/>
            <mass value="2.04"/>
            <inertia ixx="0.001053013" ixy="4.527e-05" ixz="8.855e-05" iyy="0.001805509" iyz="9.909e-05" izz="0.001765827"/>
        </inertial>
    </link>
    <!-- joint Drive output -->
    <joint name="LF_HAA" type="revolute">
        <parent link="LF_HAA"/>
        <child link="LF_HIP"/>
        <origin rpy="0 0 0" xyz="0 0 0"/>
        <axis xyz="1 0 0"/>
        <limit effort="80.0" lower="-0.72" upper="0.49" velocity="7.5"/>
        <dynamics damping="0.0" friction="0.0"/>
    </joint>
    <!-- Drive output link -->
    <link name="LF_HIP">
        <inertial>
            <origin rpy="0 0 0" xyz="0 0 0"/>
            <mass value="0.001"/>
            <inertia ixx="0.000001" ixy="0.0" ixz="0.0" iyy="0.000001" iyz="0.0" izz="0.000001"/>
        </inertial>
    </link>
    <!-- joint HAA hip -->
    <joint name="LF_HIP_LF_hip_fixed" type="fixed">
        <parent link="LF_HIP"/>
        <child link="LF_hip_fixed"/>
        <origin rpy="-2.61799387799 0 0.0" xyz="0 0 0"/>
    </joint>
    <!-- Hip link -->
    <link name="LF_hip_fixed">
        <visual>
            <origin rpy="0 0 0.0" xyz="0 0 0"/>
            <geometry>
                <mesh filename="../anymal_c_simple_description/meshes/hip_l.dae" scale="1.0 1.0 1.0"/>
            </geometry>
        </visual>
        <inertial>
            <origin rpy="0 0 0" xyz="0.048 0.008 -0.003"/>
            <mass value="0.74"/>
            <inertia ixx="0.001393106" ixy="8.4012e-05" ixz="2.3378e-05" iyy="0.003798579" iyz="7.1319e-05" izz="0.003897509"/>
        </inertial>
    </link>
    <!-- joint hip HFE -->
    <joint name="LF_hip_fixed_LF_HFE" type="fixed">
        <parent link="LF_hip_fixed"/>
        <child link="LF_HFE"/>
        <origin rpy="0 0 1.57079632679" xyz="0.0599 0.08381 0.0"/>
    </joint>
    <!-- Drive link -->
    <link name="LF_HFE">
        <visual>
            <origin rpy="0 0 0" xyz="0 0 0"/>
            <geometry>
                <mesh filename="../anymal_c_simple_description/meshes/drive.dae" scale="1.0 1.0 1.0"/>
            </geometry>
        </visual>
        <collision>
            <origin rpy="0 1.57079632679 0" xyz="-0.07 0 0"/>
            <geometry>
                <cylinder length="0.14" radius="0.05"/>
            </geometry>
        </collision>
        <inertial>
            <origin rpy="0 0 0" xyz="-0.063 7e-05 0.00046"/>
            <mass value="2.04"/>
            <inertia ixx="0.001053013" ixy="4.527e-05" ixz="8.855e-05" iyy="0.001805509" iyz="9.909e-05" izz="0.001765827"/>
        </inertial>
    </link>
    <!-- joint Drive output -->
    <joint name="LF_HFE" type="revolute">
        <parent link="LF_HFE"/>
        <child link="LF_THIGH"/>
        <origin rpy="0 0 0" xyz="0 0 0"/>
        <axis xyz="1 0 0"/>
        <limit effort="80.0" lower="-9.42477796077" upper="9.42477796077" velocity="7.5"/>
        <dynamics damping="0.0" friction="0.0"/>
    </joint>
    <!-- Drive output link -->
    <link name="LF_THIGH">
        <inertial>
            <origin rpy="0 0 0" xyz="0 0 0"/>
            <mass value="0.001"/>
            <inertia ixx="0.000001" ixy="0.0" ixz="0.0" iyy="0.000001" iyz="0.0" izz="0.000001"/>
        </inertial>
    </link>
    <!-- joint HFE thigh -->
    <joint name="LF_THIGH_LF_thigh_fixed" type="fixed">
        <parent link="LF_THIGH"/>
        <child link="LF_thigh_fixed"/>
        <origin rpy="0 0 -1.57079632679" xyz="0 0 0"/>
    </joint>
    <!-- Thigh link -->
    <link name="LF_thigh_fixed">
        <visual>
            <origin rpy="0 0 0.0" xyz="0 0 0"/>
            <geometry>
                <mesh filename="../anymal_c_simple_description/meshes/thigh.dae" scale="1.0 1.0 1.0"/>
            </geometry>
        </visual>
        <!-- Thigh collision -->
        <collision>
            <origin rpy="1.57079632679 0 0" xyz="0 0.04 0"/>
            <geometry>
                <cylinder length="0.08" radius="0.065"/>
            </geometry>
        </collision>
        <collision>
            <origin rpy="0 0 0" xyz="0 0.03 -0.1413135"/>
            <geometry>
                <box size="0.075 0.06 0.282627"/>
            </geometry>
        </collision>
        <inertial>
            <origin rpy="0 0 0" xyz="0.0 0.018 -0.169"/>
            <mass value="1.03"/>
            <inertia ixx="0.018644469" ixy="5.2e-08" ixz="1.0157e-05" iyy="0.019312599" iyz="0.002520077" izz="0.002838361"/>
        </inertial>
    </link>
    <!-- joint thigh KFE -->
    <joint name="LF_thigh_fixed_LF_KFE" type="fixed">
        <parent link="LF_thigh_fixed"/>
        <child link="LF_KFE"/>
        <origin rpy="0 0 1.57079632679" xyz="0.0 0.1003 -0.285"/>
    </joint>
    <!-- Drive link -->
    <link name="LF_KFE">
        <visual>
            <origin rpy="0 0 0" xyz="0 0 0"/>
            <geometry>
                <mesh filename="../anymal_c_simple_description/meshes/drive.dae" scale="1.0 1.0 1.0"/>
            </geometry>
        </visual>
        <collision>
            <origin rpy="0 1.57079632679 0" xyz="-0.07 0 0"/>
            <geometry>
                <cylinder length="0.14" radius="0.05"/>
            </geometry>
        </collision>
        <inertial>
            <origin rpy="0 0 0" xyz="-0.063 7e-05 0.00046"/>
            <mass value="2.04"/>
            <inertia ixx="0.001053013" ixy="4.527e-05" ixz="8.855e-05" iyy="0.001805509" iyz="9.909e-05" izz="0.001765827"/>
        </inertial>
    </link>
    <!-- joint Drive output -->
    <joint name="LF_KFE" type="revolute">
        <parent link="LF_KFE"/>
        <child link="LF_SHANK"/>
        <origin rpy="0 0 0" xyz="0 0 0"/>
        <axis xyz="1 0 0"/>
        <limit effort="80.0" lower="-9.42477796077" upper="9.42477796077" velocity="7.5"/>
        <dynamics damping="0.0" friction="0.0"/>
    </joint>
    <!-- Drive output link -->
    <link name="LF_SHANK">
        <inertial>
            <origin rpy="0 0 0" xyz="0 0 0"/>
            <mass value="0.001"/>
            <inertia ixx="0.000001" ixy="0.0" ixz="0.0" iyy="0.000001" iyz="0.0" izz="0.000001"/>
        </inertial>
    </link>
    <!-- joint KFE shank -->
    <joint name="LF_shank_LF_shank_fixed" type="fixed">
        <parent link="LF_SHANK"/>
        <child link="LF_shank_fixed"/>
        <origin rpy="0 0 -1.57079632679" xyz="0 0 0"/>
    </joint>
    <!-- Shank link -->
    <link name="LF_shank_fixed">
        <visual>
            <origin rpy="0 0 0.0" xyz="0 0 0"/>
            <geometry>
                <mesh filename="../anymal_c_simple_description/meshes/shank_l.dae" scale="1.0 1.0 1.0"/>
            </geometry>
        </visual>
        <!-- Shank collision -->
        <collision>
            <origin rpy="1.57079632679 0 0" xyz="0 0.02 0"/>
            <geometry>
                <cylinder length="0.04" radius="0.06"/>
            </geometry>
        </collision>
        <collision>
            <origin rpy="1.57079632679 0 0" xyz="0.057499 0.02 0"/>
            <geometry>
                <box size="0.114998 0.0675 0.04"/>
            </geometry>
        </collision>
        <inertial>
            <origin rpy="0 0 0" xyz="0.03463 0.00688 0.00098"/>
            <mass value="0.33742"/>
            <inertia ixx="0.00032748005" ixy="2.142561e-05" ixz="1.33942e-05" iyy="0.00110974122" iyz="7.601e-08" izz="0.00089388521"/>
        </inertial>
    </link>
    <!-- Leg configurations: xx (knees bent inwards), xo (knees bent backwards) -->
    <!-- joint shank foot -->
    <joint name="LF_shank_fixed_LF_FOOT" type="fixed">
        <parent link="LF_shank_fixed"/>
        <child link="LF_FOOT"/>
        <origin rpy="0 0 0" xyz="0.08795 0.01305 -0.33797"/>
    </joint>
    <!-- Foot link -->
    <link name="LF_FOOT">
        <visual>
            <origin rpy="0 0 -0.785398163397" xyz="0 0 0"/>
            <geometry>
                <mesh filename="../anymal_c_simple_description/meshes/foot.dae" scale="1.0 1.0 1.0"/>
            </geometry>
        </visual>
        <!-- Adapter collision -->
        <collision>
            <origin rpy="0 0 0" xyz="0 0 0.168985"/>
            <geometry>
                <cylinder length="0.282504" radius="0.0175"/>
            </geometry>
        </collision>
        <!-- Foot collision -->
        <collision>
            <origin xyz="0 0 0.0225"/>
            <geometry>
                <sphere radius="0.03"/>
            </geometry>
        </collision>
        <inertial>
            <origin rpy="0 0 0" xyz="0.00948 -0.00948 0.1468"/>
            <mass value="0.25"/>
            <inertia ixx="0.00317174097" ixy="2.63048e-06" ixz="6.815581e-05" iyy="0.00317174092" iyz="6.815583e-05" izz="8.319196e-05"/>
        </inertial>
    </link>
    <!-- joint base HAA -->
    <joint name="base_RF_HAA" type="fixed">
        <parent link="base"/>
        <child link="RF_HAA"/>
        <origin rpy="-2.61799387799 0 0.0" xyz="0.2999 -0.104 0.0"/>
    </joint>
    <!-- Drive link -->
    <link name="RF_HAA">
        <visual>
            <origin rpy="0 0 0" xyz="0 0 0"/>
            <geometry>
                <mesh filename="../anymal_c_simple_description/meshes/drive.dae" scale="1.0 1.0 1.0"/>
            </geometry>
        </visual>
        <inertial>
            <origin rpy="0 0 0" xyz="-0.063 7e-05 0.00046"/>
            <mass value="2.04"/>
            <inertia ixx="0.001053013" ixy="4.527e-05" ixz="8.855e-05" iyy="0.001805509" iyz="9.909e-05" izz="0.001765827"/>
        </inertial>
    </link>
    <!-- joint Drive output -->
    <joint name="RF_HAA" type="revolute">
        <parent link="RF_HAA"/>
        <child link="RF_HIP"/>
        <origin rpy="0 0 0" xyz="0 0 0"/>
        <axis xyz="1 0 0"/>
        <limit effort="80.0" lower="-0.49" upper="0.72" velocity="7.5"/>
        <dynamics damping="0.0" friction="0.0"/>
    </joint>
    <!-- Drive output link -->
    <link name="RF_HIP">
        <inertial>
            <origin rpy="0 0 0" xyz="0 0 0"/>
            <mass value="0.001"/>
            <inertia ixx="0.000001" ixy="0.0" ixz="0.0" iyy="0.000001" iyz="0.0" izz="0.000001"/>
        </inertial>
    </link>
    <!-- joint HAA hip -->
    <joint name="RF_HIP_RF_hip_fixed" type="fixed">
        <parent link="RF_HIP"/>
        <child link="RF_hip_fixed"/>
        <origin rpy="2.61799387799 0 0.0" xyz="0 0 0"/>
    </joint>
    <!-- Hip link -->
    <link name="RF_hip_fixed">
        <visual>
            <origin rpy="0 0 0.0" xyz="0 0 0"/>
            <geometry>
                <mesh filename="../anymal_c_simple_description/meshes/hip_r.dae" scale="1.0 1.0 1.0"/>
            </geometry>
        </visual>
        <inertial>
            <origin rpy="0 0 0" xyz="0.048 -0.008 -0.003"/>
            <mass value="0.74"/>
            <inertia ixx="0.001393106" ixy="-8.4012e-05" ixz="2.3378e-05" iyy="0.003798579" iyz="-7.1319e-05" izz="0.003897509"/>
        </inertial>
    </link>
    <!-- joint hip HFE -->
    <joint name="RF_hip_fixed_RF_HFE" type="fixed">
        <parent link="RF_hip_fixed"/>
        <child link="RF_HFE"/>
        <origin rpy="0 0 -1.57079632679" xyz="0.0599 -0.08381 0.0"/>
    </joint>
    <!-- Drive link -->
    <link name="RF_HFE">
        <visual>
            <origin rpy="0 0 0" xyz="0 0 0"/>
            <geometry>
                <mesh filename="../anymal_c_simple_description/meshes/drive.dae" scale="1.0 1.0 1.0"/>
            </geometry>
        </visual>
        <collision>
            <origin rpy="0 1.57079632679 0" xyz="-0.07 0 0"/>
            <geometry>
                <cylinder length="0.14" radius="0.05"/>
            </geometry>
        </collision>
        <inertial>
            <origin rpy="0 0 0" xyz="-0.063 7e-05 0.00046"/>
            <mass value="2.04"/>
            <inertia ixx="0.001053013" ixy="4.527e-05" ixz="8.855e-05" iyy="0.001805509" iyz="9.909e-05" izz="0.001765827"/>
        </inertial>
    </link>
    <!-- joint Drive output -->
    <joint name="RF_HFE" type="revolute">
        <parent link="RF_HFE"/>
        <child link="RF_THIGH"/>
        <origin rpy="0 0 0" xyz="0 0 0"/>
        <axis xyz="-1 0 0"/>
        <limit effort="80.0" lower="-9.42477796077" upper="9.42477796077" velocity="7.5"/>
        <dynamics damping="0.0" friction="0.0"/>
    </joint>
    <!-- Drive output link -->
    <link name="RF_THIGH">
        <inertial>
            <origin rpy="0 0 0" xyz="0 0 0"/>
            <mass value="0.001"/>
            <inertia ixx="0.000001" ixy="0.0" ixz="0.0" iyy="0.000001" iyz="0.0" izz="0.000001"/>
        </inertial>
    </link>
    <!-- joint HFE thigh -->
    <joint name="RF_THIGH_RF_thigh_fixed" type="fixed">
        <parent link="RF_THIGH"/>
        <child link="RF_thigh_fixed"/>
        <origin rpy="0 0 1.57079632679" xyz="0 0 0"/>
    </joint>
    <!-- Thigh link -->
    <link name="RF_thigh_fixed">
        <visual>
            <origin rpy="0 0 -3.14159265359" xyz="0 0 0"/>
            <geometry>
                <mesh filename="../anymal_c_simple_description/meshes/thigh.dae" scale="1.0 1.0 1.0"/>
            </geometry>
        </visual>
        <!-- Thigh collision -->
        <collision>
            <origin rpy="1.57079632679 0 0" xyz="0 -0.04 0"/>
            <geometry>
                <cylinder length="0.08" radius="0.065"/>
            </geometry>
        </collision>
        <collision>
            <origin rpy="0 0 0" xyz="0 -0.03 -0.1413135"/>
            <geometry>
                <box size="0.075 0.06 0.282627"/>
            </geometry>
        </collision>
        <inertial>
            <origin rpy="0 0 0" xyz="0.0 -0.018 -0.169"/>
            <mass value="1.03"/>
            <inertia ixx="0.018644469" ixy="-5.2e-08" ixz="1.0157e-05" iyy="0.019312599" iyz="-0.002520077" izz="0.002838361"/>
        </inertial>
    </link>
    <!-- joint thigh KFE -->
    <joint name="RF_thigh_fixed_RF_KFE" type="fixed">
        <parent link="RF_thigh_fixed"/>
        <child link="RF_KFE"/>
        <origin rpy="0 0 -1.57079632679" xyz="0.0 -0.1003 -0.285"/>
    </joint>
    <!-- Drive link -->
    <link name="RF_KFE">
        <visual>
            <origin rpy="0 0 0" xyz="0 0 0"/>
            <geometry>
                <mesh filename="../anymal_c_simple_description/meshes/drive.dae" scale="1.0 1.0 1.0"/>
            </geometry>
        </visual>
        <collision>
            <origin rpy="0 1.57079632679 0" xyz="-0.07 0 0"/>
            <geometry>
                <cylinder length="0.14" radius="0.05"/>
            </geometry>
        </collision>
        <inertial>
            <origin rpy="0 0 0" xyz="-0.063 7e-05 0.00046"/>
            <mass value="2.04"/>
            <inertia ixx="0.001053013" ixy="4.527e-05" ixz="8.855e-05" iyy="0.001805509" iyz="9.909e-05" izz="0.001765827"/>
        </inertial>
    </link>
    <!-- joint Drive output -->
    <joint name="RF_KFE" type="revolute">
        <parent link="RF_KFE"/>
        <child link="RF_SHANK"/>
        <origin rpy="0 0 0" xyz="0 0 0"/>
        <axis xyz="-1 0 0"/>
        <limit effort="80.0" lower="-9.42477796077" upper="9.42477796077" velocity="7.5"/>
        <dynamics damping="0.0" friction="0.0"/>
    </joint>
    <!-- Drive output link -->
    <link name="RF_SHANK">
        <inertial>
            <origin rpy="0 0 0" xyz="0 0 0"/>
            <mass value="0.001"/>
            <inertia ixx="0.000001" ixy="0.0" ixz="0.0" iyy="0.000001" iyz="0.0" izz="0.000001"/>
        </inertial>
    </link>
    <!-- joint KFE shank -->
    <joint name="RF_shank_RF_shank_fixed" type="fixed">
        <parent link="RF_SHANK"/>
        <child link="RF_shank_fixed"/>
        <origin rpy="0 0 1.57079632679" xyz="0 0 0"/>
    </joint>
    <!-- Shank link -->
    <link name="RF_shank_fixed">
        <visual>
            <origin rpy="0 0 0.0" xyz="0 0 0"/>
            <geometry>
                <mesh filename="../anymal_c_simple_description/meshes/shank_r.dae" scale="1.0 1.0 1.0"/>
            </geometry>
        </visual>
        <!-- Shank collision -->
        <collision>
            <origin rpy="1.57079632679 0 0" xyz="0 -0.02 0"/>
            <geometry>
                <cylinder length="0.04" radius="0.06"/>
            </geometry>
        </collision>
        <collision>
            <origin rpy="1.57079632679 0 0" xyz="0.057499 -0.02 0"/>
            <geometry>
                <box size="0.114998 0.0675 0.04"/>
            </geometry>
        </collision>
        <inertial>
            <origin rpy="0 0 0" xyz="0.03463 -0.00688 0.00098"/>
            <mass value="0.33742"/>
            <inertia ixx="0.00032748005" ixy="-2.142561e-05" ixz="1.33942e-05" iyy="0.00110974122" iyz="-7.601e-08" izz="0.00089388521"/>
        </inertial>
    </link>
    <!-- Leg configurations: xx (knees bent inwards), xo (knees bent backwards) -->
    <!-- joint shank foot -->
    <joint name="RF_shank_fixed_RF_FOOT" type="fixed">
        <parent link="RF_shank_fixed"/>
        <child link="RF_FOOT"/>
        <origin rpy="0 0 0" xyz="0.08795 -0.01305 -0.33797"/>
    </joint>
    <!-- Foot link -->
    <link name="RF_FOOT">
        <visual>
            <origin rpy="0 0 0.785398163397" xyz="0 0 0"/>
            <geometry>
                <mesh filename="../anymal_c_simple_description/meshes/foot.dae" scale="1.0 1.0 1.0"/>
            </geometry>
        </visual>
        <!-- Adapter collision -->
        <collision>
            <origin rpy="0 0 0" xyz="0 0 0.168985"/>
            <geometry>
                <cylinder length="0.282504" radius="0.0175"/>
            </geometry>
        </collision>
        <!-- Foot collision -->
        <collision>
            <origin xyz="0 0 0.0225"/>
            <geometry>
                <sphere radius="0.03"/>
            </geometry>
        </collision>
        <inertial>
            <origin rpy="0 0 0" xyz="0.00948 0.00948 0.1468"/>
            <mass value="0.25"/>
            <inertia ixx="0.00317174097" ixy="-2.63048e-06" ixz="6.815581e-05" iyy="0.00317174092" iyz="-6.815583e-05" izz="8.319196e-05"/>
        </inertial>
    </link>
    <!-- joint base HAA -->
    <joint name="base_LH_HAA" type="fixed">
        <parent link="base"/>
        <child link="LH_HAA"/>
        <origin rpy="-2.61799387799 0 -3.14159265359" xyz="-0.2999 0.104 0.0"/>
    </joint>
    <!-- Drive link -->
    <link name="LH_HAA">
        <visual>
            <origin rpy="0 0 0" xyz="0 0 0"/>
            <geometry>
                <mesh filename="../anymal_c_simple_description/meshes/drive.dae" scale="1.0 1.0 1.0"/>
            </geometry>
        </visual>
        <inertial>
            <origin rpy="0 0 0" xyz="-0.063 7e-05 0.00046"/>
            <mass value="2.04"/>
            <inertia ixx="0.001053013" ixy="4.527e-05" ixz="8.855e-05" iyy="0.001805509" iyz="9.909e-05" izz="0.001765827"/>
        </inertial>
    </link>
    <!-- joint Drive output -->
    <joint name="LH_HAA" type="revolute">
        <parent link="LH_HAA"/>
        <child link="LH_HIP"/>
        <origin rpy="0 0 0" xyz="0 0 0"/>
        <axis xyz="-1 0 0"/>
        <limit effort="80.0" lower="-0.72" upper="0.49" velocity="7.5"/>
        <dynamics damping="0.0" friction="0.0"/>
    </joint>
    <!-- Drive output link -->
    <link name="LH_HIP">
        <inertial>
            <origin rpy="0 0 0" xyz="0 0 0"/>
            <mass value="0.001"/>
            <inertia ixx="0.000001" ixy="0.0" ixz="0.0" iyy="0.000001" iyz="0.0" izz="0.000001"/>
        </inertial>
    </link>
    <!-- joint HAA hip -->
    <joint name="LH_HIP_LH_hip_fixed" type="fixed">
        <parent link="LH_HIP"/>
        <child link="LH_hip_fixed"/>
        <origin rpy="-2.61799387799 0 -3.14159265359" xyz="0 0 0"/>
    </joint>
    <!-- Hip link -->
    <link name="LH_hip_fixed">
        <visual>
            <origin rpy="0 0 -3.14159265359" xyz="0 0 0"/>
            <geometry>
                <mesh filename="../anymal_c_simple_description/meshes/hip_r.dae" scale="1.0 1.0 1.0"/>
            </geometry>
        </visual>
        <inertial>
            <origin rpy="0 0 0" xyz="-0.048 0.008 -0.003"/>
            <mass value="0.74"/>
            <inertia ixx="0.001393106" ixy="-8.4012e-05" ixz="-2.3378e-05" iyy="0.003798579" iyz="7.1319e-05" izz="0.003897509"/>
        </inertial>
    </link>
    <!-- joint hip HFE -->
    <joint name="LH_hip_fixed_LH_HFE" type="fixed">
        <parent link="LH_hip_fixed"/>
        <child link="LH_HFE"/>
        <origin rpy="0 0 1.57079632679" xyz="-0.0599 0.08381 0.0"/>
    </joint>
    <!-- Drive link -->
    <link name="LH_HFE">
        <visual>
            <origin rpy="0 0 0" xyz="0 0 0"/>
            <geometry>
                <mesh filename="../anymal_c_simple_description/meshes/drive.dae" scale="1.0 1.0 1.0"/>
            </geometry>
        </visual>
        <collision>
            <origin rpy="0 1.57079632679 0" xyz="-0.07 0 0"/>
            <geometry>
                <cylinder length="0.14" radius="0.05"/>
            </geometry>
        </collision>
        <inertial>
            <origin rpy="0 0 0" xyz="-0.063 7e-05 0.00046"/>
            <mass value="2.04"/>
            <inertia ixx="0.001053013" ixy="4.527e-05" ixz="8.855e-05" iyy="0.001805509" iyz="9.909e-05" izz="0.001765827"/>
        </inertial>
    </link>
    <!-- joint Drive output -->
    <joint name="LH_HFE" type="revolute">
        <parent link="LH_HFE"/>
        <child link="LH_THIGH"/>
        <origin rpy="0 0 0" xyz="0 0 0"/>
        <axis xyz="1 0 0"/>
        <limit effort="80.0" lower="-9.42477796077" upper="9.42477796077" velocity="7.5"/>
        <dynamics damping="0.0" friction="0.0"/>
    </joint>
    <!-- Drive output link -->
    <link name="LH_THIGH">
        <inertial>
            <origin rpy="0 0 0" xyz="0 0 0"/>
            <mass value="0.001"/>
            <inertia ixx="0.000001" ixy="0.0" ixz="0.0" iyy="0.000001" iyz="0.0" izz="0.000001"/>
        </inertial>
    </link>
    <!-- joint HFE thigh -->
    <joint name="LH_THIGH_LH_thigh_fixed" type="fixed">
        <parent link="LH_THIGH"/>
        <child link="LH_thigh_fixed"/>
        <origin rpy="0 0 -1.57079632679" xyz="0 0 0"/>
    </joint>
    <!-- Thigh link -->
    <link name="LH_thigh_fixed">
        <visual>
            <origin rpy="0 0 0.0" xyz="0 0 0"/>
            <geometry>
                <mesh filename="../anymal_c_simple_description/meshes/thigh.dae" scale="1.0 1.0 1.0"/>
            </geometry>
        </visual>
        <!-- Thigh collision -->
        <collision>
            <origin rpy="1.57079632679 0 0" xyz="0 0.04 0"/>
            <geometry>
                <cylinder length="0.08" radius="0.065"/>
            </geometry>
        </collision>
        <collision>
            <origin rpy="0 0 0" xyz="0 0.03 -0.1413135"/>
            <geometry>
                <box size="0.075 0.06 0.282627"/>
            </geometry>
        </collision>
        <inertial>
            <origin rpy="0 0 0" xyz="-0.0 0.018 -0.169"/>
            <mass value="1.03"/>
            <inertia ixx="0.018644469" ixy="-5.2e-08" ixz="-1.0157e-05" iyy="0.019312599" iyz="0.002520077" izz="0.002838361"/>
        </inertial>
    </link>
    <!-- joint thigh KFE -->
    <joint name="LH_thigh_fixed_LH_KFE" type="fixed">
        <parent link="LH_thigh_fixed"/>
        <child link="LH_KFE"/>
        <origin rpy="0 0 1.57079632679" xyz="-0.0 0.1003 -0.285"/>
    </joint>
    <!-- Drive link -->
    <link name="LH_KFE">
        <visual>
            <origin rpy="0 0 0" xyz="0 0 0"/>
            <geometry>
                <mesh filename="../anymal_c_simple_description/meshes/drive.dae" scale="1.0 1.0 1.0"/>
            </geometry>
        </visual>
        <collision>
            <origin rpy="0 1.57079632679 0" xyz="-0.07 0 0"/>
            <geometry>
                <cylinder length="0.14" radius="0.05"/>
            </geometry>
        </collision>
        <inertial>
            <origin rpy="0 0 0" xyz="-0.063 7e-05 0.00046"/>
            <mass value="2.04"/>
            <inertia ixx="0.001053013" ixy="4.527e-05" ixz="8.855e-05" iyy="0.001805509" iyz="9.909e-05" izz="0.001765827"/>
        </inertial>
    </link>
    <!-- joint Drive output -->
    <joint name="LH_KFE" type="revolute">
        <parent link="LH_KFE"/>
        <child link="LH_SHANK"/>
        <origin rpy="0 0 0" xyz="0 0 0"/>
        <axis xyz="1 0 0"/>
        <limit effort="80.0" lower="-9.42477796077" upper="9.42477796077" velocity="7.5"/>
        <dynamics damping="0.0" friction="0.0"/>
    </joint>
    <!-- Drive output link -->
    <link name="LH_SHANK">
        <inertial>
            <origin rpy="0 0 0" xyz="0 0 0"/>
            <mass value="0.001"/>
            <inertia ixx="0.000001" ixy="0.0" ixz="0.0" iyy="0.000001" iyz="0.0" izz="0.000001"/>
        </inertial>
    </link>
    <!-- joint KFE shank -->
    <joint name="LH_shank_LH_shank_fixed" type="fixed">
        <parent link="LH_SHANK"/>
        <child link="LH_shank_fixed"/>
        <origin rpy="0 0 -1.57079632679" xyz="0 0 0"/>
    </joint>
    <!-- Shank link -->
    <link name="LH_shank_fixed">
        <visual>
            <origin rpy="0 0 -3.14159265359" xyz="0 0 0"/>
            <geometry>
                <mesh filename="../anymal_c_simple_description/meshes/shank_r.dae" scale="1.0 1.0 1.0"/>
            </geometry>
        </visual>
        <!-- Shank collision -->
        <collision>
            <origin rpy="1.57079632679 0 0" xyz="0 0.02 0"/>
            <geometry>
                <cylinder length="0.04" radius="0.06"/>
            </geometry>
        </collision>
        <collision>
            <origin rpy="1.57079632679 0 0" xyz="-0.057499 0.02 0"/>
            <geometry>
                <box size="0.114998 0.0675 0.04"/>
            </geometry>
        </collision>
        <inertial>
            <origin rpy="0 0 0" xyz="-0.03463 0.00688 0.00098"/>
            <mass value="0.33742"/>
            <inertia ixx="0.00032748005" ixy="-2.142561e-05" ixz="-1.33942e-05" iyy="0.00110974122" iyz="7.601e-08" izz="0.00089388521"/>
        </inertial>
    </link>
    <!-- Leg configurations: xx (knees bent inwards), xo (knees bent backwards) -->
    <!-- joint shank foot -->
    <joint name="LH_shank_fixed_LH_FOOT" type="fixed">
        <parent link="LH_shank_fixed"/>
        <child link="LH_FOOT"/>
        <origin rpy="0 0 0" xyz="-0.08795 0.01305 -0.33797"/>
    </joint>
    <!-- Foot link -->
    <link name="LH_FOOT">
        <visual>
            <origin rpy="0 0 -2.35619449019" xyz="0 0 0"/>
            <geometry>
                <mesh filename="../anymal_c_simple_description/meshes/foot.dae" scale="1.0 1.0 1.0"/>
            </geometry>
        </visual>
        <!-- Adapter collision -->
        <collision>
            <origin rpy="0 0 0" xyz="0 0 0.168985"/>
            <geometry>
                <cylinder length="0.282504" radius="0.0175"/>
            </geometry>
        </collision>
        <!-- Foot collision -->
        <collision>
            <origin xyz="0 0 0.0225"/>
            <geometry>
                <sphere radius="0.03"/>
            </geometry>
        </collision>
        <inertial>
            <origin rpy="0 0 0" xyz="-0.00948 -0.00948 0.1468"/>
            <mass value="0.25"/>
            <inertia ixx="0.00317174097" ixy="-2.63048e-06" ixz="-6.815581e-05" iyy="0.00317174092" iyz="6.815583e-05" izz="8.319196e-05"/>
        </inertial>
    </link>
    <!-- joint base HAA -->
    <joint name="base_RH_HAA" type="fixed">
        <parent link="base"/>
        <child link="RH_HAA"/>
        <origin rpy="2.61799387799 0 -3.14159265359" xyz="-0.2999 -0.104 0.0"/>
    </joint>
    <!-- Drive link -->
    <link name="RH_HAA">
        <visual>
            <origin rpy="0 0 0" xyz="0 0 0"/>
            <geometry>
                <mesh filename="../anymal_c_simple_description/meshes/drive.dae" scale="1.0 1.0 1.0"/>
            </geometry>
        </visual>
        <inertial>
            <origin rpy="0 0 0" xyz="-0.063 7e-05 0.00046"/>
            <mass value="2.04"/>
            <inertia ixx="0.001053013" ixy="4.527e-05" ixz="8.855e-05" iyy="0.001805509" iyz="9.909e-05" izz="0.001765827"/>
        </inertial>
    </link>
    <!-- joint Drive output -->
    <joint name="RH_HAA" type="revolute">
        <parent link="RH_HAA"/>
        <child link="RH_HIP"/>
        <origin rpy="0 0 0" xyz="0 0 0"/>
        <axis xyz="-1 0 0"/>
        <limit effort="80.0" lower="-0.49" upper="0.72" velocity="7.5"/>
        <dynamics damping="0.0" friction="0.0"/>
    </joint>
    <!-- Drive output link -->
    <link name="RH_HIP">
        <inertial>
            <origin rpy="0 0 0" xyz="0 0 0"/>
            <mass value="0.001"/>
            <inertia ixx="0.000001" ixy="0.0" ixz="0.0" iyy="0.000001" iyz="0.0" izz="0.000001"/>
        </inertial>
    </link>
    <!-- joint HAA hip -->
    <joint name="RH_HIP_RH_hip_fixed" type="fixed">
        <parent link="RH_HIP"/>
        <child link="RH_hip_fixed"/>
        <origin rpy="2.61799387799 0 -3.14159265359" xyz="0 0 0"/>
    </joint>
    <!-- Hip link -->
    <link name="RH_hip_fixed">
        <visual>
            <origin rpy="0 0 -3.14159265359" xyz="0 0 0"/>
            <geometry>
                <mesh filename="../anymal_c_simple_description/meshes/hip_l.dae" scale="1.0 1.0 1.0"/>
            </geometry>
        </visual>
        <inertial>
            <origin rpy="0 0 0" xyz="-0.048 -0.008 -0.003"/>
            <mass value="0.74"/>
            <inertia ixx="0.001393106" ixy="8.4012e-05" ixz="-2.3378e-05" iyy="0.003798579" iyz="-7.1319e-05" izz="0.003897509"/>
        </inertial>
    </link>
    <!-- joint hip HFE -->
    <joint name="RH_hip_fixed_RH_HFE" type="fixed">
        <parent link="RH_hip_fixed"/>
        <child link="RH_HFE"/>
        <origin rpy="0 0 -1.57079632679" xyz="-0.0599 -0.08381 0.0"/>
    </joint>
    <!-- Drive link -->
    <link name="RH_HFE">
        <visual>
            <origin rpy="0 0 0" xyz="0 0 0"/>
            <geometry>
                <mesh filename="../anymal_c_simple_description/meshes/drive.dae" scale="1.0 1.0 1.0"/>
            </geometry>
        </visual>
        <collision>
            <origin rpy="0 1.57079632679 0" xyz="-0.07 0 0"/>
            <geometry>
                <cylinder length="0.14" radius="0.05"/>
            </geometry>
        </collision>
        <inertial>
            <origin rpy="0 0 0" xyz="-0.063 7e-05 0.00046"/>
            <mass value="2.04"/>
            <inertia ixx="0.001053013" ixy="4.527e-05" ixz="8.855e-05" iyy="0.001805509" iyz="9.909e-05" izz="0.001765827"/>
        </inertial>
    </link>
    <!-- joint Drive output -->
    <joint name="RH_HFE" type="revolute">
        <parent link="RH_HFE"/>
        <child link="RH_THIGH"/>
        <origin rpy="0 0 0" xyz="0 0 0"/>
        <axis xyz="-1 0 0"/>
        <limit effort="80.0" lower="-9.42477796077" upper="9.42477796077" velocity="7.5"/>
        <dynamics damping="0.0" friction="0.0"/>
    </joint>
    <!-- Drive output link -->
    <link name="RH_THIGH">
        <inertial>
            <origin rpy="0 0 0" xyz="0 0 0"/>
            <mass value="0.001"/>
            <inertia ixx="0.000001" ixy="0.0" ixz="0.0" iyy="0.000001" iyz="0.0" izz="0.000001"/>
        </inertial>
    </link>
    <!-- joint HFE thigh -->
    <joint name="RH_THIGH_RH_thigh_fixed" type="fixed">
        <parent link="RH_THIGH"/>
        <child link="RH_thigh_fixed"/>
        <origin rpy="0 0 1.57079632679" xyz="0 0 0"/>
    </joint>
    <!-- Thigh link -->
    <link name="RH_thigh_fixed">
        <visual>
            <origin rpy="0 0 -3.14159265359" xyz="0 0 0"/>
            <geometry>
                <mesh filename="../anymal_c_simple_description/meshes/thigh.dae" scale="1.0 1.0 1.0"/>
            </geometry>
        </visual>
        <!-- Thigh collision -->
        <collision>
            <origin rpy="1.57079632679 0 0" xyz="0 -0.04 0"/>
            <geometry>
                <cylinder length="0.08" radius="0.065"/>
            </geometry>
        </collision>
        <collision>
            <origin rpy="0 0 0" xyz="0 -0.03 -0.1413135"/>
            <geometry>
                <box size="0.075 0.06 0.282627"/>
            </geometry>
        </collision>
        <inertial>
            <origin rpy="0 0 0" xyz="-0.0 -0.018 -0.169"/>
            <mass value="1.03"/>
            <inertia ixx="0.018644469" ixy="5.2e-08" ixz="-1.0157e-05" iyy="0.019312599" iyz="-0.002520077" izz="0.002838361"/>
        </inertial>
    </link>
    <!-- joint thigh KFE -->
    <joint name="RH_thigh_fixed_RH_KFE" type="fixed">
        <parent link="RH_thigh_fixed"/>
        <child link="RH_KFE"/>
        <origin rpy="0 0 -1.57079632679" xyz="-0.0 -0.1003 -0.285"/>
    </joint>
    <!-- Drive link -->
    <link name="RH_KFE">
        <visual>
            <origin rpy="0 0 0" xyz="0 0 0"/>
            <geometry>
                <mesh filename="../anymal_c_simple_description/meshes/drive.dae" scale="1.0 1.0 1.0"/>
            </geometry>
        </visual>
        <collision>
            <origin rpy="0 1.57079632679 0" xyz="-0.07 0 0"/>
            <geometry>
                <cylinder length="0.14" radius="0.05"/>
            </geometry>
        </collision>
        <inertial>
            <origin rpy="0 0 0" xyz="-0.063 7e-05 0.00046"/>
            <mass value="2.04"/>
            <inertia ixx="0.001053013" ixy="4.527e-05" ixz="8.855e-05" iyy="0.001805509" iyz="9.909e-05" izz="0.001765827"/>
        </inertial>
    </link>
    <!-- joint Drive output -->
    <joint name="RH_KFE" type="revolute">
        <parent link="RH_KFE"/>
        <child link="RH_SHANK"/>
        <origin rpy="0 0 0" xyz="0 0 0"/>
        <axis xyz="-1 0 0"/>
        <limit effort="80.0" lower="-9.42477796077" upper="9.42477796077" velocity="7.5"/>
        <dynamics damping="0.0" friction="0.0"/>
    </joint>
    <!-- Drive output link -->
    <link name="RH_SHANK">
        <inertial>
            <origin rpy="0 0 0" xyz="0 0 0"/>
            <mass value="0.001"/>
            <inertia ixx="0.000001" ixy="0.0" ixz="0.0" iyy="0.000001" iyz="0.0" izz="0.000001"/>
        </inertial>
    </link>
    <!-- joint KFE shank -->
    <joint name="RH_shank_RH_shank_fixed" type="fixed">
        <parent link="RH_SHANK"/>
        <child link="RH_shank_fixed"/>
        <origin rpy="0 0 1.57079632679" xyz="0 0 0"/>
    </joint>
    <!-- Shank link -->
    <link name="RH_shank_fixed">
        <visual>
            <origin rpy="0 0 -3.14159265359" xyz="0 0 0"/>
            <geometry>
                <mesh filename="../anymal_c_simple_description/meshes/shank_l.dae" scale="1.0 1.0 1.0"/>
            </geometry>
        </visual>
        <!-- Shank collision -->
        <collision>
            <origin rpy="1.57079632679 0 0" xyz="0 -0.02 0"/>
            <geometry>
                <cylinder length="0.04" radius="0.06"/>
            </geometry>
        </collision>
        <collision>
            <origin rpy="1.57079632679 0 0" xyz="-0.057499 -0.02 0"/>
            <geometry>
                <box size="0.114998 0.0675 0.04"/>
            </geometry>
        </collision>
        <inertial>
            <origin rpy="0 0 0" xyz="-0.03463 -0.00688 0.00098"/>
            <mass value="0.33742"/>
            <inertia ixx="0.00032748005" ixy="2.142561e-05" ixz="-1.33942e-05" iyy="0.00110974122" iyz="-7.601e-08" izz="0.00089388521"/>
        </inertial>
    </link>
    <!-- Leg configurations: xx (knees bent inwards), xo (knees bent backwards) -->
    <!-- joint shank foot -->
    <joint name="RH_shank_fixed_RH_FOOT" type="fixed">
        <parent link="RH_shank_fixed"/>
        <child link="RH_FOOT"/>
        <origin rpy="0 0 0" xyz="-0.08795 -0.01305 -0.33797"/>
    </joint>
    <!-- Foot link -->
    <link name="RH_FOOT">
        <visual>
            <origin rpy="0 0 -3.92699081699" xyz="0 0 0"/>
            <geometry>
                <mesh filename="../anymal_c_simple_description/meshes/foot.dae" scale="1.0 1.0 1.0"/>
            </geometry>
        </visual>
        <!-- Adapter collision -->
        <collision>
            <origin rpy="0 0 0" xyz="0 0 0.168985"/>
            <geometry>
                <cylinder length="0.282504" radius="0.0175"/>
            </geometry>
        </collision>
        <!-- Foot collision -->
        <collision>
            <origin xyz="0 0 0.0225"/>
            <geometry>
                <sphere radius="0.03"/>
            </geometry>
        </collision>
        <inertial>
            <origin rpy="0 0 0" xyz="-0.00948 0.00948 0.1468"/>
            <mass value="0.25"/>
            <inertia ixx="0.00317174097" ixy="2.63048e-06" ixz="-6.815581e-05" iyy="0.00317174092" iyz="-6.815583e-05" izz="8.319196e-05"/>
        </inertial>
    </link>
    <!-- Fixed joint base hatch -->
    <joint name="base_hatch" type="fixed">
        <parent link="base"/>
        <child link="hatch"/>
        <origin rpy="0 0 0" xyz="0.0 0.0 0.0"/>
    </joint>
    <!-- Hatch link -->
    <link name="hatch">
        <visual>
            <origin rpy="0 0 0" xyz="0.116 0 0.073"/>
            <geometry>
                <mesh filename="../anymal_c_simple_description/meshes/hatch.dae" scale="1.0 1.0 1.0"/>
            </geometry>
        </visual>
        <inertial>
            <origin rpy="0 0 0" xyz="0.116 0.0 0.0758"/>
            <mass value="0.142"/>
            <inertia ixx="0.001" ixy="0.001" ixz="0.001" iyy="0.001" iyz="0.001" izz="0.001"/>
        </inertial>
    </link>

    <!-- Here starts the kinova urdf -->
    <!-- <joint name="arm_to_anymal" type="fixed">
        <origin rpy="0 0 0" xyz="0.116 0 0.0825"/>
        <parent link="base"/>   
        <child link="base_link"/>
    </joint> -->
    <joint name="arm_to_anymal" type="fixed">
        <!-- <origin rpy="0 0 0" xyz="0.35801 0 0.073"/> -->
        <origin rpy="0 0 0" xyz="0.49801 0 0.063"/>
        <parent link="base"/>   
        <child link="base_link"/>
    </joint>
    <link name="base_link">
        <inertial>
        <origin rpy="0 0 0" xyz="-0.000648 -0.000166 0.084487"/>
        <mass value="1.697"/>
        <!-- <mass value="0.697"/> -->
        <!-- <mass value="1E-06"/> -->
        <inertia ixx="0.004622" ixy="9E-06" ixz="6E-05" iyy="0.004495" iyz="9E-06" izz="0.002079"/>
        </inertial>
        <visual>
        <origin rpy="0 0 0" xyz="0 0 0"/>
        <geometry>
            <mesh filename="../kortex_description/arms/gen3/6dof/meshes/base_link.STL"/>
        </geometry>
        <material name="">
            <color rgba="0.75294 0.75294 0.75294 1"/>
        </material>
        </visual>
        <collision>
        <origin rpy="0 0 0" xyz="0 0 0.085425"/>
        <geometry>
            <cylinder length="0.17085" radius="0.056032"/>
        </geometry>
        </collision>
    </link>
    <link name="shoulder_link">
        <inertial>
        <origin rpy="0 0 0" xyz="-2.3E-05 -0.010364 -0.07336"/>
        <mass value="1.377"/>
        <!-- <mass value="0.377"/> -->
        <!-- <mass value="1E-06"/> -->
        <inertia ixx="0.00457" ixy="1E-06" ixz="2E-06" iyy="0.004831" iyz="0.000448" izz="0.001409"/>
        </inertial>
        <visual>
        <origin rpy="0 0 0" xyz="0 0 0"/>
        <geometry>
            <mesh filename="../kortex_description/arms/gen3/6dof/meshes/shoulder_link.STL"/>
        </geometry>
        <material name="">
            <color rgba="0.75294 0.75294 0.75294 1"/>
        </material>
        </visual>
        <collision>
        <origin rpy="0 0 0" xyz="0 0 -0.07169"/>
        <geometry>
            <cylinder length="0.11338" radius="0.051"/>
        </geometry>
        </collision>
    </link>
    <joint name="joint_1" type="continuous">
        <origin rpy="-3.1416 0.0 0.0" xyz="0 0 0.15643"/>
        <parent link="base_link"/>
        <child link="shoulder_link"/>
        <axis xyz="0 0 1"/>
        <limit effort="39" velocity="1.3963"/>
    </joint>
    <link name="bicep_link">
        <inertial>
        <origin rpy="0 0 0" xyz="3.5E-05 -0.208207 -0.01889"/>
        <mass value="1.262"/>
        <!-- <mass value="0.262"/> -->
        <!-- <mass value="1E-06"/> -->
        <inertia ixx="0.046752" ixy="-9E-06" ixz="0" iyy="0.00085" iyz="-9.8E-05" izz="0.047188"/>
        </inertial>
        <visual>
        <origin rpy="0 0 0" xyz="0 0 0"/>
        <geometry>
            <mesh filename="../kortex_description/arms/gen3/6dof/meshes/bicep_link.STL"/>
        </geometry>
        <material name="">
            <color rgba="0.75294 0.75294 0.75294 1"/>
        </material>
        </visual>
        <collision>
        <origin rpy="1.5708 0 0" xyz="0 -0.205 -0.03"/>
        <geometry>
            <cylinder length="0.41" radius="0.028772"/>
        </geometry>
        </collision>
    </link>
    <joint name="joint_2" type="revolute">
        <origin rpy="1.5708 0.0 0.0" xyz="0 0.005375 -0.12838"/>
        <parent link="shoulder_link"/>
        <child link="bicep_link"/>
        <axis xyz="0 0 1"/>
        <limit effort="39" lower="-2.41" upper="2.41" velocity="1.3963"/>
    </joint>
    <link name="forearm_link">
        <inertial>
        <origin rpy="0 0 0" xyz="1.8E-05 0.076168 -0.01397"/>
        <mass value="0.93"/>
        <!-- <mass value="0.23"/> -->
        <!-- <mass value="1E-06"/> -->
        <inertia ixx="0.008292" ixy="-1E-06" ixz="0" iyy="0.000628" iyz="0.000432" izz="0.008464"/>
        </inertial>
        <visual>
        <origin rpy="0 0 0" xyz="0 0 0"/>
        <geometry>
            <mesh filename="../kortex_description/arms/gen3/6dof/meshes/forearm_link.STL"/>
        </geometry>
        <material name="">
            <color rgba="0.75294 0.75294 0.75294 1"/>
        </material>
        </visual>
        <collision>
        <origin rpy="-1.5708 0 0" xyz="0 0.104215 -0.02"/>
        <geometry>
            <cylinder length="0.20843" radius="0.043772"/>
        </geometry>
        </collision>
    </link>
    <joint name="joint_3" type="revolute">
        <origin rpy="3.1416 0 0" xyz="0 -0.41 0"/>
        <parent link="bicep_link"/>
        <child link="forearm_link"/>
        <axis xyz="0 0 1"/>
        <limit effort="39" lower="-2.66" upper="2.66" velocity="1.3963"/>
    </joint>
    <link name="spherical_wrist_1_link">
        <inertial>
        <origin rpy="0 0 0" xyz="-1E-06 0.008486 -0.062937"/>
        <mass value="0.6781"/>
        <!-- <mass value="0.1781"/> -->
        <!-- <mass value="1E-06"/> -->
        <inertia ixx="0.001645" ixy="0" ixz="0" iyy="0.001666" iyz="-0.000234" izz="0.000389"/>
        </inertial>
        <visual>
        <origin rpy="0 0 0" xyz="0 0 0"/>
        <geometry>
            <mesh filename="../kortex_description/arms/gen3/6dof/meshes/spherical_wrist_1_link.STL"/>
        </geometry>
        <material name="">
            <color rgba="0.75294 0.75294 0.75294 1"/>
        </material>
        </visual>
        <collision>
        <origin rpy="0 0 0" xyz="0 0 -0.052965"/>
        <geometry>
            <cylinder length="0.10593" radius="0.043772"/>
        </geometry>
        </collision>
    </link>
    <joint name="joint_4" type="continuous">
        <origin rpy="1.5708 0.0 0.0" xyz="0 0.20843 -0.006375"/>
        <parent link="forearm_link"/>
        <child link="spherical_wrist_1_link"/>
        <axis xyz="0 0 1"/>
        <limit effort="9" velocity="1.2218"/>
    </joint>
    <link name="spherical_wrist_2_link">
        <inertial>
        <origin rpy="0 0 0" xyz="-1E-06 0.046429 -0.008704"/>
        <mass value="0.678"/>
        <!-- <mass value="0.178"/> -->
        <!-- <mass value="1E-06"/> -->
        <inertia ixx="0.001685" ixy="0" ixz="0" iyy="0.0004" iyz="0.000255" izz="0.001696"/>
        </inertial>
        <visual>
        <origin rpy="0 0 0" xyz="0 0 0"/>
        <geometry>
            <mesh filename="../kortex_description/arms/gen3/6dof/meshes/spherical_wrist_2_link.STL"/>
        </geometry>
        <material name="">
            <color rgba="0.75294 0.75294 0.75294 1"/>
        </material>
        </visual>
        <collision>
        <origin rpy="-1.5708 0 0" xyz="0 0.052965 0"/>
        <geometry>
            <cylinder length="0.10593" radius="0.043772"/>
        </geometry>
        </collision>
    </link>
    <joint name="joint_5" type="revolute">
        <origin rpy="-1.5708 0.0 0.0" xyz="0 -0.00017505 -0.10593"/>
        <parent link="spherical_wrist_1_link"/>
        <child link="spherical_wrist_2_link"/>
        <axis xyz="0 0 1"/>
        <limit effort="9" lower="-2.23" upper="2.23" velocity="1.2218"/>
    </joint>
    <link name="bracelet_link">
        <inertial>
        <origin rpy="0 0 0" xyz="0.000281 0.011402 -0.029798"/>
        <mass value="0.5"/>
        <!-- <mass value="0.2"/> -->
        <!-- <mass value="1E-06"/> -->
        <inertia ixx="0.000587" ixy="3E-06" ixz="3E-06" iyy="0.000369" iyz="-0.000118" izz="0.000609"/>
        </inertial>
        <visual>
        <origin rpy="0 0 0" xyz="0 0 0"/>
        <geometry>
            <mesh filename="../kortex_description/arms/gen3/6dof/meshes/bracelet_with_vision_link.STL"/>
        </geometry>
        <material name="">
            <color rgba="0.75294 0.75294 0.75294 1"/>
        </material>
        </visual>
        <collision>
        <origin rpy="0 0 0" xyz="0 0 -0.0307625"/>
        <geometry>
            <cylinder length="0.061525" radius="0.043772"/>
        </geometry>
        </collision>
    </link>
    <joint name="joint_6" type="continuous">
        <origin rpy="1.5708 0.0 0.0" xyz="0 0.10593 -0.00017505"/>
        <parent link="spherical_wrist_2_link"/>
        <child link="bracelet_link"/>
        <axis xyz="0 0 1"/>
        <limit effort="9" velocity="1.2218"/>
    </joint>
    <link name="end_effector_link"/>
    <joint name="end_effector" type="fixed">
        <origin rpy="3.14159265358979 1.09937075168372E-32 3.14159265358979" xyz="0 0 -0.0615250000000001"/>
        <parent link="bracelet_link"/>
        <child link="end_effector_link"/>
        <axis xyz="0 0 0"/>
    </joint>
    <!-- This line was removed by Kinova because we replaced the transmission file with our own 
        <xacro:include filename="$(find robotiq_2f_85_gripper_visualization)/urdf/robotiq_arg2f_transmission.xacro" /> -->
    <!-- Tool frame used by the arm -->
    <link name="tool_frame"/>
    <joint name="tool_frame_joint" type="fixed">
        <origin rpy="0 0 0" xyz="0 0 0.120"/>
        <parent link="end_effector_link"/>
        <child link="tool_frame"/>
        <axis xyz="0 0 0"/>
    </joint>
    <!-- This joint was added by Kinova -->
    <joint name="gripper_base_joint" type="fixed">
        <parent link="end_effector_link"/>
        <child link="robotiq_arg2f_base_link"/>
        <origin rpy="0.0 0.0 1.57" xyz="0.0 0.0 0.0"/>
    </joint>
    <link name="robotiq_arg2f_base_link">
        <inertial>
        <origin rpy="0 0 0" xyz="8.625E-08 -4.6583E-06 0.03145"/>
        <mass value="0.22652"/>
        <!-- <mass value="0.02652"/> -->
        <!-- <mass value="1E-06"/> -->
        <inertia ixx="0.00020005" ixy="-4.2442E-10" ixz="-2.9069E-10" iyy="0.00017832" iyz="-3.4402E-08" izz="0.00013478"/>
        </inertial>
        <visual>
        <origin rpy="0 0 0" xyz="0 0 0"/>
        <geometry>
            <!-- The DAE file doesn't show well in Gazebo so we're using the STL instead -->
            <!-- <mesh filename="../kortex_description/grippers/robotiq_2f_85/meshes/visual/robotiq_arg2f_85_base_link.dae" scale="0.001 0.001 0.001"/> -->
            <mesh filename="../kortex_description/grippers/robotiq_2f_85/meshes/collision/robotiq_arg2f_base_link.stl"/>
        </geometry>
        <material name="">
            <color rgba="0.1 0.1 0.1 1"/>
        </material>
        </visual>
        <collision>
        <origin rpy="0 0 0" xyz="0 0 0.0457635"/>
        <geometry>
            <cylinder length="0.091527" radius="0.043772"/>
        </geometry>
        </collision>
    </link>
    <gazebo reference="robotiq_arg2f_base_link">
        <material>Gazebo/Black</material>
    </gazebo>
    <link name="left_outer_knuckle">
        <inertial>
        <origin rpy="0 0 0" xyz="-0.000200000000003065 0.0199435877845359 0.0292245259211331"/>
        <mass value="0.00853198276973456"/>
        <!-- <mass value="1E-06"/> -->
        <inertia ixx="2.89328108496468E-06" ixy="-1.57935047237397E-19" ixz="-1.93980378593255E-19" iyy="1.86719750325683E-06" iyz="-1.21858577871576E-06" izz="1.21905238907251E-06"/>
        </inertial>
        <visual>
        <origin rpy="0 0 0" xyz="0 0 0"/>
        <geometry>
            <mesh filename="../kortex_description/grippers/robotiq_2f_85/meshes/visual/robotiq_arg2f_85_outer_knuckle.dae" scale="0.001 0.001 0.001"/>
        </geometry>
        <material name="">
            <color rgba="0.792156862745098 0.819607843137255 0.933333333333333 1"/>
        </material>
        </visual>
        <collision>
        <origin rpy="0 0 0" xyz="0 0 0"/>
        <geometry>
            <mesh filename="../kortex_description/grippers/robotiq_2f_85/meshes/collision/robotiq_arg2f_85_outer_knuckle.obj" scale="0.001 0.001 0.001"/>
        </geometry>
        </collision>
    </link>
    <link name="left_outer_finger">
        <inertial>
        <origin rpy="0 0 0" xyz="0.00030115855001899 0.0373907951953854 -0.0208027427000385"/>
        <mass value="0.022614240507152"/>
        <!-- <mass value="1E-06"/> -->
        <inertia ixx="1.52518312458174E-05" ixy="9.76583423954399E-10" ixz="-5.43838577022588E-10" iyy="6.17694243867776E-06" iyz="6.78636130740228E-06" izz="1.16494917907219E-05"/>
        </inertial>
        <visual>
        <origin rpy="0 0 0" xyz="0 0 0"/>
        <geometry>
            <mesh filename="../kortex_description/grippers/robotiq_2f_85/meshes/visual/robotiq_arg2f_85_outer_finger.dae" scale="0.001 0.001 0.001"/>
        </geometry>
        <material name="">
            <color rgba="0.1 0.1 0.1 1"/>
        </material>
        </visual>
        <collision>
        <origin rpy="0 0 0" xyz="0 0 0"/>
        <geometry>
            <mesh filename="../kortex_description/grippers/robotiq_2f_85/meshes/collision/robotiq_arg2f_85_outer_finger.obj" scale="0.001 0.001 0.001"/>
        </geometry>
        </collision>
    </link>
    <link name="left_inner_finger">
        <inertial>
        <origin rpy="0 0 0" xyz="0.000299999999999317 0.0160078233491243 -0.0136945669206257"/>
        <mass value="0.0104003125914103"/>
        <!-- <mass value="1E-06"/> -->
        <inertia ixx="2.71909453810972E-06" ixy="1.35402465472579E-21" ixz="-7.1817349065269E-22" iyy="7.69100314106116E-07" iyz="6.74715432769696E-07" izz="2.30315190420171E-06"/>
        </inertial>
        <visual>
        <origin rpy="0 0 0" xyz="0 0 0"/>
        <geometry>
            <mesh filename="../kortex_description/grippers/robotiq_2f_85/meshes/visual/robotiq_arg2f_85_inner_finger.dae" scale="0.001 0.001 0.001"/>
        </geometry>
        <material name="">
            <color rgba="0.1 0.1 0.1 1"/>
        </material>
        </visual>
        <collision>
        <origin rpy="0 0 0" xyz="0 0 0"/>
        <geometry>
            <mesh filename="../kortex_description/grippers/robotiq_2f_85/meshes/collision/robotiq_arg2f_85_inner_finger.obj" scale="0.001 0.001 0.001"/>
        </geometry>
        </collision>
    </link>
    <link name="left_inner_finger_pad">
        <visual>
        <origin rpy="0 0 0" xyz="0 0 0"/>
        <geometry>
            <box size="0.022 0.00635 0.0375"/>
        </geometry>
        <material name="">
            <color rgba="0.9 0.9 0.9 1"/>
        </material>
        </visual>
        <collision>
        <!-- <origin rpy="0 0 0" xyz="0 0 0"/> -->
        <origin rpy="0 0 0" xyz="0 0 0"/>
        <geometry>
            <!-- <box size="0.022 0.00635 0.0375"/> -->
            <box size="0.022 0.01035 0.0375"/>
        </geometry>
        <material name="">
            <color rgba="0.9 0.0 0.0 1"/>
        </material>
        </collision>
    </link>
    <link name="left_inner_knuckle">
        <inertial>
        <origin rpy="0 0 0" xyz="0.000123011831763771 0.0507850843201817 0.00103968640075166"/>
        <mass value="0.0271177346495152"/>
        <!-- <mass value="1E-06"/> -->
        <inertia ixx="2.61910379223783E-05" ixy="-2.43616858946494E-07" ixz="-6.37789906117123E-09" iyy="2.8270243746167E-06" iyz="-5.37200748039765E-07" izz="2.83695868220296E-05"/>
        </inertial>
        <visual>
        <origin rpy="0 0 0" xyz="0 0 0"/>
        <geometry>
            <mesh filename="../kortex_description/grippers/robotiq_2f_85/meshes/visual/robotiq_arg2f_85_inner_knuckle.dae" scale="0.001 0.001 0.001"/>
        </geometry>
        <material name="">
            <color rgba="0.1 0.1 0.1 1"/>
        </material>
        </visual>
        <collision>
        <origin rpy="0 0 0" xyz="0 0 0"/>
        <geometry>
            <mesh filename="../kortex_description/grippers/robotiq_2f_85/meshes/collision/robotiq_arg2f_85_inner_knuckle.obj" scale="0.001 0.001 0.001"/>
        </geometry>
        </collision>
    </link>
    <link name="right_outer_knuckle">
        <inertial>
        <origin rpy="0 0 0" xyz="-0.000200000000003065 0.0199435877845359 0.0292245259211331"/>
        <mass value="0.00853198276973456"/>
        <!-- <mass value="1E-06"/> -->
        <inertia ixx="2.89328108496468E-06" ixy="-1.57935047237397E-19" ixz="-1.93980378593255E-19" iyy="1.86719750325683E-06" iyz="-1.21858577871576E-06" izz="1.21905238907251E-06"/>
        </inertial>
        <visual>
        <origin rpy="0 0 0" xyz="0 0 0"/>
        <geometry>
            <mesh filename="../kortex_description/grippers/robotiq_2f_85/meshes/visual/robotiq_arg2f_85_outer_knuckle.dae" scale="0.001 0.001 0.001"/>
        </geometry>
        <material name="">
            <color rgba="0.792156862745098 0.819607843137255 0.933333333333333 1"/>
        </material>
        </visual>
        <collision>
        <origin rpy="0 0 0" xyz="0 0 0"/>
        <geometry>
            <mesh filename="../kortex_description/grippers/robotiq_2f_85/meshes/collision/robotiq_arg2f_85_outer_knuckle.obj" scale="0.001 0.001 0.001"/>
        </geometry>
        </collision>
    </link>
    <link name="right_outer_finger">
        <inertial>
        <origin rpy="0 0 0" xyz="0.00030115855001899 0.0373907951953854 -0.0208027427000385"/>
        <mass value="0.022614240507152"/>
        <!-- <mass value="1E-06"/> -->
        <inertia ixx="1.52518312458174E-05" ixy="9.76583423954399E-10" ixz="-5.43838577022588E-10" iyy="6.17694243867776E-06" iyz="6.78636130740228E-06" izz="1.16494917907219E-05"/>
        </inertial>
        <visual>
        <origin rpy="0 0 0" xyz="0 0 0"/>
        <geometry>
            <mesh filename="../kortex_description/grippers/robotiq_2f_85/meshes/visual/robotiq_arg2f_85_outer_finger.dae" scale="0.001 0.001 0.001"/>
        </geometry>
        <material name="">
            <color rgba="0.1 0.1 0.1 1"/>
        </material>
        </visual>
        <collision>
        <origin rpy="0 0 0" xyz="0 0 0"/>
        <geometry>
            <mesh filename="../kortex_description/grippers/robotiq_2f_85/meshes/collision/robotiq_arg2f_85_outer_finger.obj" scale="0.001 0.001 0.001"/>
        </geometry>
        </collision>
    </link>
    <link name="right_inner_finger">
        <inertial>
        <origin rpy="0 0 0" xyz="0.000299999999999317 0.0160078233491243 -0.0136945669206257"/>
        <mass value="0.0104003125914103"/>
        <!-- <mass value="1E-06"/> -->
        <inertia ixx="2.71909453810972E-06" ixy="1.35402465472579E-21" ixz="-7.1817349065269E-22" iyy="7.69100314106116E-07" iyz="6.74715432769696E-07" izz="2.30315190420171E-06"/>
        </inertial>
        <visual>
        <origin rpy="0 0 0" xyz="0 0 0"/>
        <geometry>
            <mesh filename="../kortex_description/grippers/robotiq_2f_85/meshes/visual/robotiq_arg2f_85_inner_finger.dae" scale="0.001 0.001 0.001"/>
        </geometry>
        <material name="">
            <color rgba="0.1 0.1 0.1 1"/>
        </material>
        </visual>
        <collision>
        <origin rpy="0 0 0" xyz="0 0 0"/>
        <geometry>
            <mesh filename="../kortex_description/grippers/robotiq_2f_85/meshes/collision/robotiq_arg2f_85_inner_finger.obj" scale="0.001 0.001 0.001"/>
        </geometry>
        </collision>
    </link>
    <link name="right_inner_finger_pad">
        <visual>
        <origin rpy="0 0 0" xyz="0 0 0"/>
        <geometry>
            <box size="0.022 0.00635 0.0375"/>
        </geometry>
        <material name="">
            <color rgba="0.9 0.9 0.9 1"/>
        </material>
        </visual>
        <collision>
        <!-- <origin rpy="0 0 0" xyz="0 0 0"/> -->
        <origin rpy="0 0 0" xyz="0 0 0"/>
        <geometry>
            <!-- <box size="0.022 0.00635 0.0375"/> -->
            <box size="0.022 0.01035 0.0375"/>
        </geometry>
        <material name="">
            <color rgba="0.9 0.0 0.0 1"/>
        </material>
        </collision>
    </link>
    <link name="right_inner_knuckle">
        <inertial>
        <origin rpy="0 0 0" xyz="0.000123011831763771 0.0507850843201817 0.00103968640075166"/>
        <mass value="0.0271177346495152"/>
        <!-- <mass value="1E-06"/> -->
        <inertia ixx="2.61910379223783E-05" ixy="-2.43616858946494E-07" ixz="-6.37789906117123E-09" iyy="2.8270243746167E-06" iyz="-5.37200748039765E-07" izz="2.83695868220296E-05"/>
        </inertial>
        <visual>
        <origin rpy="0 0 0" xyz="0 0 0"/>
        <geometry>
            <mesh filename="../kortex_description/grippers/robotiq_2f_85/meshes/visual/robotiq_arg2f_85_inner_knuckle.dae" scale="0.001 0.001 0.001"/>
        </geometry>
        <material name="">
            <color rgba="0.1 0.1 0.1 1"/>
        </material>
        </visual>
        <collision>
        <origin rpy="0 0 0" xyz="0 0 0"/>
        <geometry>
            <mesh filename="../kortex_description/grippers/robotiq_2f_85/meshes/collision/robotiq_arg2f_85_inner_knuckle.obj" scale="0.001 0.001 0.001"/>
        </geometry>
        </collision>
    </link>
    <joint name="finger_joint" type="revolute">
        <origin rpy="0 0 3.141592653589793" xyz="0 -0.0306011 0.054904"/>
        <parent link="robotiq_arg2f_base_link"/>
        <child link="left_outer_knuckle"/>
        <axis xyz="1 0 0"/>
        <limit effort="1000" lower="0" upper="0.8" velocity="2.0"/>
    </joint>
    <joint name="left_outer_finger_joint" type="fixed">
        <origin rpy="0 0 0" xyz="0 0.0315 -0.0041"/>
        <parent link="left_outer_knuckle"/>
        <child link="left_outer_finger"/>
        <axis xyz="1 0 0"/>
    </joint>
    <joint name="left_inner_knuckle_joint" type="revolute">
        <!-- <origin xyz="0 ${reflect * -0.0127} 0.06142" rpy="${pi / 2 + .725} 0 ${(reflect - 1) * pi / 2}" /> -->
        <origin rpy="0 0 3.141592653589793" xyz="0 -0.0127 0.06142"/>
        <parent link="robotiq_arg2f_base_link"/>
        <child link="left_inner_knuckle"/>
        <axis xyz="1 0 0"/>
        <limit effort="1000" lower="0" upper="0.8757" velocity="2.0"/>
        <mimic joint="finger_joint" multiplier="1" offset="0"/>
    </joint>
    <joint name="left_inner_finger_joint" type="revolute">
        <origin rpy="0 0 0" xyz="0 0.0061 0.0471"/>
        <parent link="left_outer_finger"/>
        <child link="left_inner_finger"/>
        <axis xyz="1 0 0"/>
        <limit effort="1000" lower="-0.8757" upper="0.8757" velocity="2.0"/>
        <mimic joint="finger_joint" multiplier="-1" offset="0"/>
    </joint>
    <joint name="left_inner_finger_pad_joint" type="fixed">
        <origin rpy="0 0 0" xyz="0 -0.0220203446692936 0.03242"/>
        <parent link="left_inner_finger"/>
        <child link="left_inner_finger_pad"/>
        <axis xyz="0 0 1"/>
    </joint>
    <joint name="right_outer_knuckle_joint" type="revolute">
        <origin rpy="0 0 0" xyz="0 0.0306011 0.054904"/>
        <parent link="robotiq_arg2f_base_link"/>
        <child link="right_outer_knuckle"/>
        <axis xyz="1 0 0"/>
        <limit effort="1000" lower="0" upper="0.81" velocity="2.0"/>
        <mimic joint="finger_joint" multiplier="1" offset="0"/>
    </joint>
    <joint name="right_outer_finger_joint" type="fixed">
        <origin rpy="0 0 0" xyz="0 0.0315 -0.0041"/>
        <parent link="right_outer_knuckle"/>
        <child link="right_outer_finger"/>
        <axis xyz="1 0 0"/>
    </joint>
    <joint name="right_inner_knuckle_joint" type="revolute">
        <!-- <origin xyz="0 ${reflect * -0.0127} 0.06142" rpy="${pi / 2 + .725} 0 ${(reflect - 1) * pi / 2}" /> -->
        <origin rpy="0 0 0.0" xyz="0 0.0127 0.06142"/>
        <parent link="robotiq_arg2f_base_link"/>
        <child link="right_inner_knuckle"/>
        <axis xyz="1 0 0"/>
        <limit effort="1000" lower="0" upper="0.8757" velocity="2.0"/>
        <mimic joint="finger_joint" multiplier="1" offset="0"/>
    </joint>
    <joint name="right_inner_finger_joint" type="revolute">
        <origin rpy="0 0 0" xyz="0 0.0061 0.0471"/>
        <parent link="right_outer_finger"/>
        <child link="right_inner_finger"/>
        <axis xyz="1 0 0"/>
        <limit effort="1000" lower="-0.8757" upper="0.8757" velocity="2.0"/>
        <mimic joint="finger_joint" multiplier="-1" offset="0"/>
    </joint>
    <joint name="right_inner_finger_pad_joint" type="fixed">
        <origin rpy="0 0 0" xyz="0 -0.0220203446692936 0.03242"/>
        <parent link="right_inner_finger"/>
        <child link="right_inner_finger_pad"/>
        <axis xyz="0 0 1"/>
    </joint>
    <!-- Transmissions are loaded in the generic kortex xacro when simulation is enabled -->
    <!-- <xacro:robotiq_arg2f_transmission prefix="${prefix}"/> -->
    <transmission name="joint_1_transmission">
        <type>transmission_interface/SimpleTransmission</type>
        <joint name="joint_1">
        <hardwareInterface>hardware_interface/EffortJointInterface</hardwareInterface>
        </joint>
        <actuator name="joint_1_motor">
        <mechanicalReduction>1</mechanicalReduction>
        </actuator>
    </transmission>
    <transmission name="joint_2_transmission">
        <type>transmission_interface/SimpleTransmission</type>
        <joint name="joint_2">
        <hardwareInterface>hardware_interface/EffortJointInterface</hardwareInterface>
        </joint>
        <actuator name="joint_2_motor">
        <mechanicalReduction>1</mechanicalReduction>
        </actuator>
    </transmission>
    <transmission name="joint_3_transmission">
        <type>transmission_interface/SimpleTransmission</type>
        <joint name="joint_3">
        <hardwareInterface>hardware_interface/EffortJointInterface</hardwareInterface>
        </joint>
        <actuator name="joint_3_motor">
        <mechanicalReduction>1</mechanicalReduction>
        </actuator>
    </transmission>
    <transmission name="joint_4_transmission">
        <type>transmission_interface/SimpleTransmission</type>
        <joint name="joint_4">
        <hardwareInterface>hardware_interface/EffortJointInterface</hardwareInterface>
        </joint>
        <actuator name="joint_4_motor">
        <mechanicalReduction>1</mechanicalReduction>
        </actuator>
    </transmission>
    <transmission name="joint_5_transmission">
        <type>transmission_interface/SimpleTransmission</type>
        <joint name="joint_5">
        <hardwareInterface>hardware_interface/EffortJointInterface</hardwareInterface>
        </joint>
        <actuator name="joint_5_motor">
        <mechanicalReduction>1</mechanicalReduction>
        </actuator>
    </transmission>
    <transmission name="joint_6_transmission">
        <type>transmission_interface/SimpleTransmission</type>
        <joint name="joint_6">
        <hardwareInterface>hardware_interface/EffortJointInterface</hardwareInterface>
        </joint>
        <actuator name="joint_6_motor">
        <mechanicalReduction>1</mechanicalReduction>
        </actuator>
    </transmission>
    <transmission name="finger_joint_trans">
        <type>transmission_interface/SimpleTransmission</type>
        <joint name="finger_joint">
        <hardwareInterface>hardware_interface/PositionJointInterface</hardwareInterface>
        </joint>
        <actuator name="finger_joint_motor">
        <mechanicalReduction>1</mechanicalReduction>
        <hardwareInterface>hardware_interface/PositionJointInterface</hardwareInterface>
        </actuator>
    </transmission>
    <gazebo>
        <plugin filename="libroboticsgroup_upatras_gazebo_mimic_joint_plugin.so" name="mimic_robotiq_85_1">
        <joint>finger_joint</joint>
        <mimicJoint>right_outer_knuckle_joint</mimicJoint>
        <multiplier>1.0</multiplier>
        <offset>0.0</offset>
        <maxEffort>5.0</maxEffort>
        <hasPID/>
        </plugin>
        <plugin filename="libroboticsgroup_upatras_gazebo_mimic_joint_plugin.so" name="mimic_robotiq_85_2">
        <joint>finger_joint</joint>
        <mimicJoint>right_inner_knuckle_joint</mimicJoint>
        <multiplier>1.0</multiplier>
        <offset>0.0</offset>
        <maxEffort>5.0</maxEffort>
        <hasPID/>
        </plugin>
        <plugin filename="libroboticsgroup_upatras_gazebo_mimic_joint_plugin.so" name="mimic_robotiq_85_3">
        <joint>finger_joint</joint>
        <mimicJoint>left_inner_knuckle_joint</mimicJoint>
        <multiplier>1.0</multiplier>
        <offset>0.0</offset>
        <maxEffort>5.0</maxEffort>
        <hasPID/>
        </plugin>
        <plugin filename="libroboticsgroup_upatras_gazebo_mimic_joint_plugin.so" name="mimic_robotiq_85_4">
        <joint>finger_joint</joint>
        <mimicJoint>left_inner_finger_joint</mimicJoint>
        <multiplier>-1.0</multiplier>
        <offset>0.0</offset>
        <maxEffort>5.0</maxEffort>
        <hasPID/>
        </plugin>
        <plugin filename="libroboticsgroup_upatras_gazebo_mimic_joint_plugin.so" name="mimic_robotiq_85_5">
        <joint>finger_joint</joint>
        <mimicJoint>right_inner_finger_joint</mimicJoint>
        <multiplier>-1.0</multiplier>
        <offset>0.0</offset>
        <maxEffort>5.0</maxEffort>
        <hasPID/>
        </plugin>
        <plugin filename="libgazebo_grasp_fix.so" name="gazebo_grasp_fix">
        <arm>
            <arm_name>my_robotiq_gripper</arm_name>
            <palm_link>bracelet_link</palm_link>
            <!-- Gazebo merges links connected by fixed joints, so here we would have put gripper_base_link but it is merged with Bracelet_Link internally -->
            <gripper_link> left_inner_finger </gripper_link>
            <gripper_link> right_inner_finger </gripper_link>
        </arm>
        <forces_angle_tolerance>100</forces_angle_tolerance>
        <update_rate>10</update_rate>
        <grip_count_threshold>3</grip_count_threshold>
        <max_grip_count>10</max_grip_count>
        <release_tolerance>0.001</release_tolerance>
        <disable_collisions_on_attach>false</disable_collisions_on_attach>
        <contact_topic>__default_topic__</contact_topic>
        </plugin>
    </gazebo>
    <gazebo>
        <plugin filename="libgazebo_ros_control.so" name="gazebo_ros_control">
        <legacyModeNS>true</legacyModeNS>
        </plugin>
    </gazebo>    
</robot>

