<robot name="biped">
    <link name="world">  </link>
    <link name="dummy">  
      <collision>
        <origin rpy="0 0 0" xyz="0 0 0"/>
        <geometry>
            <box size="0.00 0.00 0.00"/>
        </geometry>
      </collision>
      <inertial>
        <origin rpy="0 0 0" xyz="0.0 0.0 0.0"/>
        <mass value="0.0"/>
        <inertia ixx="0.0" ixy="0.0" ixz="0.0" iyy="0.0" iyz="0.0" izz="0.0"/>
      </inertial>    
    </link>
    <joint name="world_joint_dummy" type="fixed">
        <origin xyz="0.00000 0.00000 0.00000" rpy="0.0 0.0 0.0"/>
        <parent link="world"/>
        <child  link="dummy"/>
    </joint>
    <link name="z_axis_link">  
      <collision>
        <origin rpy="0 0 0" xyz="0 0 0"/>
        <geometry>
            <box size="0.0 0.0 0.0"/>
        </geometry>
      </collision>
      <inertial>
        <origin rpy="0 0 0" xyz="0.0 0.0 0.0"/>
        <mass value="0.0"/>
        <inertia ixx="0.0" ixy="0.0" ixz="0.0" iyy="0.0" iyz="0.0" izz="0.0"/>
      </inertial>    
    </link>  
    <joint name="dummy_joint_z_axis_link" type="prismatic">
        <origin xyz="0.00000 0.00000 0.00000" rpy="0.0 0.0 0.0"/>
        <parent link="dummy"/>
        <child  link="z_axis_link"/>
        <limit effort="2000" lower="-100.6" upper="100.6" velocity="100.0"/>
        <axis xyz="0 0 1"/>
    </joint>  
    <link name="base">
	    <visual>
	      <geometry>
	        <box size="0.30 0.30 0.30"/>
	      </geometry>
	      <material name="gray">
	        <color rgba="0.3 0.3 0.3 1.0"/>
	      </material>
	    </visual>    
      <collision>
        <origin rpy="0 0 0" xyz="0 0 0"/>
        <geometry>
            <box size="0.30 0.30 0.30"/>
        </geometry>
      </collision>
      <inertial>
        <origin rpy="0 0 0" xyz="0.0 0.0 0.0"/>
        <mass value="3.0"/>
        <inertia ixx="0.045" ixy="0.0" ixz="0.0" iyy="0.045" iyz="0.0" izz="0.045"/>
      </inertial>	        
    </link>
    <joint name="z_axis_link_joint_base" type="prismatic">
        <origin xyz="0.00000 0.00000 0.00000" rpy="0.0 0.0 0.0"/>
        <parent link="z_axis_link"/>
        <child  link="base"/>
        <limit effort="2000" lower="-100.6" upper="100.6" velocity="100.0"/>
        <axis xyz="1 0 0"/>
    </joint>  
    <!-- <joint name="base_joint_world" type="prismatic">
      <origin xyz="0.00000 0.00000 0.00000" rpy="0.0 0.0 0.0"/>
      <parent link="dummy"/>
      <child  link="base"/>
      <limit effort="2000" lower="-100.6" upper="100.6" velocity="100.0"/>
      <axis xyz="0 0 1"/>
    </joint>     -->
    
    <!-- LEFT LEG -->
    <link name="L_hipassembly">
	    <visual>
	      <origin rpy="0.0 0.0 0.0" xyz="0.0 0.0 0.0"/>
	      <geometry>
	        <mesh filename="../meshes/leg/hipassembly.dae" scale="1 1 1"/>
	      </geometry>
	      <material name="white"/>
	    </visual>    
      <collision>
        <origin rpy="0 1.5707962290814481 0" xyz="0.04 0.0 0.0"/>
        <geometry>
            <cylinder length="0.08" radius="0.035"/>
        </geometry>
      </collision>
      <inertial>
        <origin rpy="0 0 0" xyz="0.05 0.0 0.0"/>
        <mass value="0.5"/>
        <inertia ixx="0.00030625" ixy="0.0" ixz="0.0" iyy="0.0004198" iyz="0.0" izz="0.0004198"/>
      </inertial>	     
    </link>
    <link name="L_upperleg">
	    <visual>
	      <origin rpy="0.0 0.0 0.0" xyz="0.0 0.0 0.0"/>
	      <geometry>
	        <mesh filename="../meshes/leg/upperleg.dae" scale="1 1 1"/>
	      </geometry>
	      <material name="blue"/>
	    </visual>
      <collision>
        <origin rpy="0 1.5707962290814481 0" xyz="0.175 0.0 0.0"/>
        <geometry>
            <cylinder length="0.35" radius="0.045"/>
        </geometry>
      </collision>
      <inertial>
        <origin rpy="0 0 0" xyz="0.175 0.0 0.0"/>
        <mass value="1.5"/>
        <inertia ixx="0.0015188" ixy="0.0" ixz="0.0" iyy="0.016072" iyz="0.0" izz="0.016072"/>
      </inertial>	
    </link>
    <link name="L_lowerleg">
	    <visual>
	      <geometry>
	        <mesh filename="../meshes/leg/lowerleg.dae" scale="1 1 1"/>
	      </geometry>
	      <material name="blue"/>
	    </visual> 
      <collision>
        <origin rpy="0 1.5707962290814481 0" xyz="0.17 0.0 0.0"/>
        <geometry>
            <cylinder length="0.34" radius="0.015"/>
        </geometry>
      </collision>
      <inertial>
        <origin rpy="0 0 0" xyz="0.17 0.0 0.0"/>
        <mass value="1.0"/>
        <inertia ixx="0.0001125" ixy="0.0" ixz="0.0" iyy="0.00969" iyz="0.0" izz="0.00969"/>
      </inertial>	       
    </link>
    <link name="L_foot">
      <collision>
        <origin rpy="0 0 0" xyz="0.0 0.0 0.0"/>
        <geometry>
            <sphere radius="0.03"/>
        </geometry>
      </collision>
      <inertial>
        <origin rpy="0 0 0" xyz="0.0 0.0 0.0"/>
        <mass value="0.25"/>
        <inertia ixx="0.00015" ixy="0.0" ixz="0.0" iyy="0.00015" iyz="0.0" izz="0.00015"/>
      </inertial>	       
    </link>
    
    <joint name="L_haa_joint" type="fixed">
        <origin xyz="0.00000 0.1 -0.15000" rpy="2.0344439357957036 1.5707962290814481 -1.1071487177940917"/>
        <parent link="base"/>
        <child  link="L_hipassembly"/>
        <!-- <limit effort="200" lower="-1.6" upper="1.6" velocity="1.0"/> -->
        <limit effort="200" lower="-1.6" upper="1.6" velocity="100.0"/>
        <!-- <axis xyz="0 0 1"/> -->
    </joint>
    <joint name="L_hfe_joint" type="revolute">
        <origin xyz="0.08000 0.00000 0.00000" rpy="1.5707963705062866 -0.0 0.0"/>
        <parent link="L_hipassembly"/>
        <child  link="L_upperleg"/>
        <!-- <limit effort="200" lower="-1.6" upper="1.6" velocity="1.0"/> -->
        <limit effort="200" lower="-1.6" upper="1.6" velocity="100.0"/>
        <axis xyz="0 0 1"/>
    </joint>
    <joint name="L_kfe_joint" type="revolute">
        <origin xyz="0.35000 0.00000 0.00000" rpy="0.0 0.0 0.0"/>
        <parent link="L_upperleg"/>
        <child  link="L_lowerleg"/>
        <!-- <limit effort="200" lower="-1.6" upper="1.6" velocity="1.0"/> -->
        <limit effort="200" lower="-1.6" upper="1.6" velocity="100.0"/>
        <axis xyz="0 0 1"/>
    </joint>
    <joint name="L_foot_joint" type="fixed">
        <origin xyz="0.34000 0.00000 0.00000" rpy="0.0 0.0 0.0"/>
        <parent link="L_lowerleg"/>
        <child  link="L_foot"/>
    </joint>
    
    
    
    <!-- RIGHT LEG -->
    <link name="R_hipassembly">
      <visual>
        <origin rpy="0.0 0.0 0.0" xyz="0.0 0.0 0.0"/>
        <geometry>
          <mesh filename="../meshes/leg/hipassembly.dae" scale="1 1 1"/>
        </geometry>
        <material name="white"/>
      </visual>  
      <collision>
        <origin rpy="0 1.5707962290814481 0" xyz="0.04 0.0 0.0"/>
        <geometry>
            <cylinder length="0.08" radius="0.035"/>
        </geometry>
      </collision>
      <inertial>
        <origin rpy="0 0 0" xyz="0.05 0.0 0.0"/>
        <mass value="0.5"/>
        <inertia ixx="0.00030625" ixy="0.0" ixz="0.0" iyy="0.0004198" iyz="0.0" izz="0.0004198"/>
      </inertial>	       
    </link>
    <link name="R_upperleg">
      <visual>
        <origin rpy="0.0 0.0 0.0" xyz="0.0 0.0 0.0"/>
        <geometry>
          <mesh filename="../meshes/leg/upperleg.dae" scale="1 1 1"/>
        </geometry>
        <material name="blue"/>
      </visual>
      <collision>
        <origin rpy="0 1.5707962290814481 0" xyz="0.175 0.0 0.0"/>
        <geometry>
            <cylinder length="0.35" radius="0.045"/>
        </geometry>
      </collision>
      <inertial>
        <origin rpy="0 0 0" xyz="0.175 0.0 0.0"/>
        <mass value="1.5"/>
        <inertia ixx="0.0015188" ixy="0.0" ixz="0.0" iyy="0.016072" iyz="0.0" izz="0.016072"/>
      </inertial>
    </link>
    <link name="R_lowerleg">
      <visual>
        <geometry>
          <mesh filename="../meshes/leg/lowerleg.dae" scale="1 1 1"/>
        </geometry>
        <material name="blue"/>
      </visual> 
      <collision>
        <origin rpy="0 1.5707962290814481 0" xyz="0.17 0.0 0.0"/>
        <geometry>
            <cylinder length="0.34" radius="0.015"/>
        </geometry>
      </collision>
      <inertial>
        <origin rpy="0 0 0" xyz="0.17 0.0 0.0"/>
        <mass value="1.0"/>
        <inertia ixx="0.0001125" ixy="0.0" ixz="0.0" iyy="0.00969" iyz="0.0" izz="0.00969"/>
      </inertial>	       
    </link>
    <link name="R_foot">
      <collision>
        <origin rpy="0 0 0" xyz="0.0 0.0 0.0"/>
        <geometry>
            <sphere radius="0.03"/>
        </geometry>
      </collision>
      <inertial>
        <origin rpy="0 0 0" xyz="0.0 0.0 0.0"/>
        <mass value="0.25"/>
        <inertia ixx="0.00015" ixy="0.0" ixz="0.0" iyy="0.00015" iyz="0.0" izz="0.00015"/>
      </inertial>	       
    </link>
    
    <joint name="R_haa_joint" type="fixed">
        <origin xyz="0.00000 -0.1 -0.15000" rpy="2.0344439357957036 1.5707962290814481 -1.1071487177940917"/>
        <parent link="base"/>
        <child  link="R_hipassembly"/>
        <!-- <limit effort="200" lower="-1.6" upper="1.6" velocity="1.0"/> -->
        <limit effort="200" lower="-1.6" upper="1.6" velocity="100.0"/>
        <!-- <axis xyz="0 0 1"/> -->
    </joint>
    <joint name="R_hfe_joint" type="revolute">
        <origin xyz="0.08000 0.00000 0.00000" rpy="1.5707963705062866 -0.0 0.0"/>
        <parent link="R_hipassembly"/>
        <child  link="R_upperleg"/>
        <!-- <limit effort="200" lower="-1.6" upper="1.6" velocity="1.0"/> -->
        <limit effort="200" lower="-1.6" upper="1.6" velocity="100.0"/>
        <axis xyz="0 0 1"/>
    </joint>
    <joint name="R_kfe_joint" type="revolute">
        <origin xyz="0.35000 0.00000 0.00000" rpy="0.0 0.0 0.0"/>
        <parent link="R_upperleg"/>
        <child  link="R_lowerleg"/>
        <!-- <limit effort="200" lower="-1.6" upper="1.6" velocity="1.0"/> -->
        <limit effort="200" lower="-1.6" upper="1.6" velocity="100.0"/>
        <axis xyz="0 0 1"/>
    </joint>
    <joint name="R_foot_joint" type="fixed">
        <origin xyz="0.34000 0.00000 0.00000" rpy="0.0 0.0 0.0"/>
        <parent link="R_lowerleg"/>
        <child  link="R_foot"/>
    </joint>
    
    
</robot>

